Workbook

Sheet Dev Phase ->

Sheet Board Report (Dev) 
A1: PROJECT Budget
A2: CLR Silsbee PO LLC
A3: Application Period: 12.2024
A4: Requisition:
B6: Requisition Total | C6: Approved Budget | D6: $/RSF | E6: Payment To Date | F6: Balance To Pay | G6: % Paid | I6: Project NRSF
B7: LAND | C7: ='Budget to Actual P1'!G13 -> 0 | D7: =C7/$I$7 -> 0 | E7: ='Budget to Actual P1'!J13 -> 0 | F7: ='Budget to Actual P1'!L13 -> 0 | G7: =IF(ISERROR(E7/C7),0,E7/C7) -> 0 | I7: 222677
B8: SITEWORK | C8: ='Budget to Actual P1'!G18 -> 0 | D8: =C8/$I$7 -> 0 | E8: ='Budget to Actual P1'!J18 -> 0 | F8: ='Budget to Actual P1'!L18 -> 0 | G8: =IF(ISERROR(E8/C8),0,E8/C8) -> 0
B9: CONSTRUCTION - BASE | C9: ='Budget to Actual P1'!G28 -> 6379396.9 | D9: =C9/$I$7 -> 28.648657 | E9: ='Budget to Actual P1'!J28 -> 5467355.1 | F9: ='Budget to Actual P1'!L28 -> 912041.77 | G9: =IF(ISERROR(E9/C9),0,E9/C9) -> 0.85703323
B10: PERMITS AND FEES | C10: ='Budget to Actual P1'!G44 -> 0 | D10: =C10/$I$7 -> 0 | E10: ='Budget to Actual P1'!J44 -> 0 | F10: ='Budget to Actual P1'!L44 -> 0 | G10: =IF(ISERROR(E10/C10),0,E10/C10) -> 0
B11: DESIGN AND ENGINEERING CONSULTANTS | C11: ='Budget to Actual P1'!G67 -> 164385.7 | D11: =C11/$I$7 -> 0.73822487 | E11: ='Budget to Actual P1'!J67 -> 164385.7 | F11: ='Budget to Actual P1'!L67 -> 0 | G11: =IF(ISERROR(E11/C11),0,E11/C11) -> 1
B12: FINANCING | C12: ='Budget to Actual P1'!G92 -> 2586495.5 | D12: =C12/$I$7 -> 11.615459 | E12: ='Budget to Actual P1'!J92 -> 735654.03 | F12: ='Budget to Actual P1'!L92 -> 1850841.5 | G12: =IF(ISERROR(E12/C12),0,E12/C12) -> 0.28442115
B13: OTHER DEVELOPMENT COSTS | C13: ='Budget to Actual P1'!G113 -> 329018.68 | D13: =C13/$I$7 -> 1.4775602 | E13: ='Budget to Actual P1'!J113 -> 291272.48 | F13: ='Budget to Actual P1'!L113 -> 37746.205 | G13: =IF(ISERROR(E13/C13),0,E13/C13) -> 0.88527641
B14: LEASING AND MARKETING | C14: ='Budget to Actual P1'!G124 -> 1416100.7 | D14: =C14/$I$7 -> 6.3594386 | E14: ='Budget to Actual P1'!J124 -> 917186.84 | F14: ='Budget to Actual P1'!L124 -> 498913.86 | G14: =IF(ISERROR(E14/C14),0,E14/C14) -> 0.64768476
B15: TOTAL PROJECT COSTS | C15: =SUM(C7:C14) -> 10875398 | D15: =SUM(D7:D14) -> 48.839339 | E15: =SUM(E7:E14) -> 7575854.2 | F15: =SUM(F7:F14) -> 3299543.3 | G15: =E15/C15 -> 0.69660481
C16: ='Budget to Actual P1'!G126-C15 -> 0 | E16: =E15-'Budget to Actual P1'!J126 -> 0 | F16: =F15-'Budget to Actual P1'!L126 -> 0

Sheet Budget to Actual P1
H1: change date in line #9 | I1: change date in line #9 | J1: change date in line #9 | L1: 2026-07-31
B2: County Line Rail Silsbee LLC
B3: Budget to Actual
B4: 46234
D7: Silsbee PO | E7: Previous Contingency | F7: Current Contingency | G7: Silsbee PO | H7: Previous Application | I7: Payment this period | J7: Total Complete & Draw To Date | L7: Balance remaining
B8: GL Coding | C8: Account Name | D8: Approved Budget | E8: Funding & Reallocation | F8: Funding & Reallocation | G8: Current Approved Budget | H8: Inception to 06/30/2026 | I8: 7/31/2026 | J8: Incurred to 7/31/2026 | K8: Percent Drawn | L8: As of 7/31/2026
C10: Land Purchase | D10: 0 | E10: 0 | F10: 0 | G10: =+D10+E10+F10 -> 0 | H10: =SUMIF('Prior Invoice Log P1'!C:C,'Budget to Actual P1'!B10,'Prior Invoice Log P1'!G:G) -> 0 | I10: =SUMIF('Current Invoice Log P1'!C:C,'Budget to Actual P1'!B10,'Current Invoice Log P1'!G:G) -> 0 | J10: =SUM(H10,I10) -> 0 | K10: =J10/G10 -> #DIV/0! | L10: =+G10-J10 -> 0
B11: 11010 | C11: Acquisitions Costs (Land Purchase) | D11: 0 | E11: 0 | F11: 0 | G11: =+D11+E11+F11 -> 0 | H11: =SUMIF('Prior Invoice Log P1'!C:C,'Budget to Actual P1'!B11,'Prior Invoice Log P1'!G:G) -> 0 | I11: =SUMIF('Current Invoice Log P1'!C:C,'Budget to Actual P1'!B11,'Current Invoice Log P1'!G:G) -> 0 | J11: =SUM(H11:I11) -> 0 | K11: =J11/G11 -> #DIV/0! | L11: =+G11-J11 -> 0
C12: Other Land Costs | D12: 0 | E12: 0 | F12: 0 | G12: =+D12+E12+F12 -> 0 | H12: =SUMIF('Prior Invoice Log P1'!C:C,'Budget to Actual P1'!B12,'Prior Invoice Log P1'!G:G) -> 0 | I12: =SUMIF('Current Invoice Log P1'!C:C,'Budget to Actual P1'!B12,'Current Invoice Log P1'!G:G) -> 0 | J12: =SUM(H12,I12) -> 0 | K12: =J12/G12 -> #DIV/0! | L12: =+G12-J12 -> 0
C13: Total Land Cost | D13: =SUBTOTAL(9,D10:D12) -> 0 | E13: =SUBTOTAL(9,E10:E12) -> 0 | F13: =SUBTOTAL(9,F10:F12) -> 0 | G13: =SUBTOTAL(9,G10:G12) -> 0 | H13: =SUBTOTAL(9,H10:H12) -> 0 | I13: =SUBTOTAL(9,I10:I12) -> 0 | J13: =SUBTOTAL(9,J10:J12) -> 0 | K13: =J13/G13 -> #DIV/0! | L13: =SUBTOTAL(9,L10:L12) -> 0
C14: Demolition | D14: 0 | E14: 0 | F14: 0 | G14: =+D14+E14+F14 -> 0 | H14: =SUMIF('Prior Invoice Log P1'!C:C,'Budget to Actual P1'!B14,'Prior Invoice Log P1'!G:G) -> 0 | I14: =SUMIF('Current Invoice Log P1'!C:C,'Budget to Actual P1'!B14,'Current Invoice Log P1'!G:G) -> 0 | J14: =SUM(H14,I14) -> 0 | K14: =J14/G14 -> #DIV/0! | L14: =+G14-J14 -> 0
C15: Offsite Utilities | D15: 0 | E15: 0 | F15: 0 | G15: =+D15+E15+F15 -> 0 | H15: =SUMIF('Prior Invoice Log P1'!C:C,'Budget to Actual P1'!B15,'Prior Invoice Log P1'!G:G) -> 0 | I15: =SUMIF('Current Invoice Log P1'!C:C,'Budget to Actual P1'!B15,'Current Invoice Log P1'!G:G) -> 0 | J15: =SUM(H15,I15) -> 0 | K15: =J15/G15 -> #DIV/0! | L15: =+G15-J15 -> 0
C16: Site Work | D16: 0 | E16: 0 | F16: 0 | G16: =+D16+E16+F16 -> 0 | H16: =SUMIF('Prior Invoice Log P1'!C:C,'Budget to Actual P1'!B16,'Prior Invoice Log P1'!G:G) -> 0 | I16: =SUMIF('Current Invoice Log P1'!C:C,'Budget to Actual P1'!B16,'Current Invoice Log P1'!G:G) -> 0 | J16: =SUM(H16,I16) -> 0 | K16: =J16/G16 -> #DIV/0! | L16: =+G16-J16 -> 0
C17: Utilities Relocation | D17: 0 | E17: 0 | F17: 0 | G17: =+D17+E17+F17 -> 0 | H17: =SUMIF('Prior Invoice Log P1'!C:C,'Budget to Actual P1'!B17,'Prior Invoice Log P1'!G:G) -> 0 | I17: =SUMIF('Current Invoice Log P1'!C:C,'Budget to Actual P1'!B17,'Current Invoice Log P1'!G:G) -> 0 | J17: =SUM(H17,I17) -> 0 | K17: =J17/G17 -> #DIV/0! | L17: =+G17-J17 -> 0
C18: Total Site Work | D18: =SUBTOTAL(9,D14:D17) -> 0 | E18: =SUBTOTAL(9,E14:E17) -> 0 | F18: =SUBTOTAL(9,F14:F17) -> 0 | G18: =SUBTOTAL(9,G14:G17) -> 0 | H18: =SUBTOTAL(9,H14:H17) -> 0 | I18: =SUBTOTAL(9,I14:I17) -> 0 | J18: =SUBTOTAL(9,J14:J17) -> 0 | K18: =IFERROR(J18/G18,0) -> 0 | L18: =SUBTOTAL(9,L14:L17) -> 0
B19: 11230-1 | C19: Yard Stabilization | D19: 100000 | E19: 2678658.4 | F19: 0 | G19: =+D19+E19+F19 -> 2778658.4 | H19: =SUMIF('Prior Invoice Log P1'!C:C,'Budget to Actual P1'!B19,'Prior Invoice Log P1'!G:G) -> 2778658.4 | I19: =SUMIF('Current Invoice Log P1'!C:C,'Budget to Actual P1'!B19,'Current Invoice Log P1'!G:G) -> 0 | J19: =SUM(H19,I19) -> 2778658.4 | K19: =J19/G19 -> 1 | L19: =+G19-J19 -> 0
B20: 11230-2 | C20: Warehouse Improvements | D20: 814195 | E20: 336094.78 | F20: 0 | G20: =+D20+E20+F20 -> 1150289.8 | H20: =SUMIF('Prior Invoice Log P1'!C:C,'Budget to Actual P1'!B20,'Prior Invoice Log P1'!G:G) -> 1150289.8 | I20: =SUMIF('Current Invoice Log P1'!C:C,'Budget to Actual P1'!B20,'Current Invoice Log P1'!G:G) -> 0 | J20: =SUM(H20,I20) -> 1150289.8 | K20: =J20/G20 -> 1 | L20: =+G20-J20 -> 0
B21: 11230-3 | C21: Sprinkler Improvements | D21: 143563 | E21: 480944 | F21: 0 | G21: =+D21+E21+F21 -> 624507 | H21: =SUMIF('Prior Invoice Log P1'!C:C,'Budget to Actual P1'!B21,'Prior Invoice Log P1'!G:G) -> 537651.9 | I21: =SUMIF('Current Invoice Log P1'!C:C,'Budget to Actual P1'!B21,'Current Invoice Log P1'!G:G) -> 86855.1 | J21: =SUM(H21,I21) -> 624507 | K21: =J21/G21 -> 1 | L21: =+G21-J21 -> 0
B22: 11230-4 | C22: Roof Improvements | D22: 210385 | E22: 300 | F22: 0 | G22: =+D22+E22+F22 -> 210685 | H22: =SUMIF('Prior Invoice Log P1'!C:C,'Budget to Actual P1'!B22,'Prior Invoice Log P1'!G:G) -> 210685 | I22: =SUMIF('Current Invoice Log P1'!C:C,'Budget to Actual P1'!B22,'Current Invoice Log P1'!G:G) -> 0 | J22: =SUM(H22,I22) -> 210685 | K22: =J22/G22 -> 1 | L22: =+G22-J22 -> 0
B23: 11230-5 | C23: Electrical Improvements | D23: 222358 | E23: 79782.64 | F23: 0 | G23: =+D23+E23+F23 -> 302140.64 | H23: =SUMIF('Prior Invoice Log P1'!C:C,'Budget to Actual P1'!B23,'Prior Invoice Log P1'!G:G) -> 206823.46 | I23: =SUMIF('Current Invoice Log P1'!C:C,'Budget to Actual P1'!B23,'Current Invoice Log P1'!G:G) -> 95317.18 | J23: =SUM(H23,I23) -> 302140.64 | K23: =J23/G23 -> 1 | L23: =+G23-J23 -> 0
B24: 11230-6 | C24: Fencing | D24: 650000 | E24: 0 | F24: 0 | G24: =+D24+E24+F24 -> 650000 | H24: =SUMIF('Prior Invoice Log P1'!C:C,'Budget to Actual P1'!B24,'Prior Invoice Log P1'!G:G) -> 112500 | I24: =SUMIF('Current Invoice Log P1'!C:C,'Budget to Actual P1'!B24,'Current Invoice Log P1'!G:G) -> 0 | J24: =SUM(H24,I24) -> 112500 | K24: =J24/G24 -> 0.17307692 | L24: =+G24-J24 -> 537500
B25: 11230-7 | C25: Other Hard Costs | D25: 83393 | E25: 205181.29 | F25: 0 | G25: =+D25+E25+F25 -> 288574.29 | H25: =SUMIF('Prior Invoice Log P1'!C:C,'Budget to Actual P1'!B25,'Prior Invoice Log P1'!G:G) -> 288574.29 | I25: =SUMIF('Current Invoice Log P1'!C:C,'Budget to Actual P1'!B25,'Current Invoice Log P1'!G:G) -> 0 | J25: =SUM(H25,I25) -> 288574.29 | K25: =J25/G25 -> 1 | L25: =+G25-J25 -> 0
B26: 11216 | C26: Hard Cost Contingency | D26: 346282.8 | E26: -221655.29 | F26: 0 | G26: =+D26+E26+F26 -> 124627.51 | H26: =SUMIF('Prior Invoice Log P1'!C:C,'Budget to Actual P1'!B26,'Prior Invoice Log P1'!G:G) -> 0 | I26: =SUMIF('Current Invoice Log P1'!C:C,'Budget to Actual P1'!B26,'Current Invoice Log P1'!G:G) -> 0 | J26: =SUM(H26,I26) -> 0 | K26: =IFERROR(J26/G26,) -> 0 | L26: =+G26-J26 -> 124627.51
B27: 11217 | C27: Soft Cost Contingency | D27: 293570.38 | E27: -43656.12 | F27: 0 | G27: =+D27+E27+F27 -> 249914.26 | H27: =SUMIF('Prior Invoice Log P1'!C:C,'Budget to Actual P1'!B27,'Prior Invoice Log P1'!G:G) -> 0 | I27: =SUMIF('Current Invoice Log P1'!C:C,'Budget to Actual P1'!B27,'Current Invoice Log P1'!G:G) -> 0 | J27: =SUM(H27,I27) -> 0 | K27: =J27/G27 -> 0 | L27: =+G27-J27 -> 249914.26
C28: Construction Costs | D28: =SUBTOTAL(9,D19:D27) -> 2863747.2 | E28: 3515649.7 | F28: 0 | G28: =SUBTOTAL(9,G19:G27) -> 6379396.9 | H28: =SUBTOTAL(9,H19:H27) -> 5285182.9 | I28: =SUBTOTAL(9,I19:I27) -> 182172.28 | J28: =SUBTOTAL(9,J19:J27) -> 5467355.1 | K28: =J28/G28 -> 0.85703323 | L28: =SUBTOTAL(9,L19:L27) -> 912041.77
C29: Sanitary Charges | D29: 0 | E29: 0 | F29: 0 | G29: =+D29+E29+F29 -> 0 | H29: =SUMIF('Prior Invoice Log P1'!C:C,'Budget to Actual P1'!B29,'Prior Invoice Log P1'!G:G) -> 0 | I29: =SUMIF('Current Invoice Log P1'!C:C,'Budget to Actual P1'!B29,'Current Invoice Log P1'!G:G) -> 0 | J29: =SUM(H29,I29) -> 0 | K29: =IFERROR(J29/G29,0) -> 0 | L29: =+G29-J29 -> 0
C30: Water Charges | D30: 0 | E30: 0 | F30: 0 | G30: =+D30+E30+F30 -> 0 | H30: =SUMIF('Prior Invoice Log P1'!C:C,'Budget to Actual P1'!B30,'Prior Invoice Log P1'!G:G) -> 0 | I30: =SUMIF('Current Invoice Log P1'!C:C,'Budget to Actual P1'!B30,'Current Invoice Log P1'!G:G) -> 0 | J30: =SUM(H30,I30) -> 0 | K30: =IFERROR(J30/G30,0) -> 0 | L30: =+G30-J30 -> 0
C31: Building Permits | D31: 0 | E31: 0 | F31: 0 | G31: =+D31+E31+F31 -> 0 | H31: =SUMIF('Prior Invoice Log P1'!C:C,'Budget to Actual P1'!B31,'Prior Invoice Log P1'!G:G) -> 0 | I31: =SUMIF('Current Invoice Log P1'!C:C,'Budget to Actual P1'!B31,'Current Invoice Log P1'!G:G) -> 0 | J31: =SUM(H31,I31) -> 0 | K31: =IFERROR(J31/G31,0) -> 0 | L31: =+G31-J31 -> 0
C32: CO Fees | D32: 0 | E32: 0 | F32: 0 | G32: =+D32+E32+F32 -> 0 | H32: =SUMIF('Prior Invoice Log P1'!C:C,'Budget to Actual P1'!B32,'Prior Invoice Log P1'!G:G) -> 0 | I32: =SUMIF('Current Invoice Log P1'!C:C,'Budget to Actual P1'!B32,'Current Invoice Log P1'!G:G) -> 0 | J32: =SUM(H32,I32) -> 0 | K32: =IFERROR(J32/G32,0) -> 0 | L32: =+G32-J32 -> 0
C33: A&E Permit Fees | D33: 0 | E33: 0 | F33: 0 | G33: =+D33+E33+F33 -> 0 | H33: =SUMIF('Prior Invoice Log P1'!C:C,'Budget to Actual P1'!B33,'Prior Invoice Log P1'!G:G) -> 0 | I33: =SUMIF('Current Invoice Log P1'!C:C,'Budget to Actual P1'!B33,'Current Invoice Log P1'!G:G) -> 0 | J33: =SUM(H33,I33) -> 0 | K33: =IFERROR(J33/G33,0) -> 0 | L33: =+G33-J33 -> 0
C34: File & Review Fees | D34: 0 | E34: 0 | F34: 0 | G34: =+D34+E34+F34 -> 0 | H34: =SUMIF('Prior Invoice Log P1'!C:C,'Budget to Actual P1'!B34,'Prior Invoice Log P1'!G:G) -> 0 | I34: =SUMIF('Current Invoice Log P1'!C:C,'Budget to Actual P1'!B34,'Current Invoice Log P1'!G:G) -> 0 | J34: =SUM(H34,I34) -> 0 | K34: =IFERROR(J34/G34,0) -> 0 | L34: =+G34-J34 -> 0
C35: Tax Abatement | D35: 0 | E35: 0 | F35: 0 | G35: =+D35+E35+F35 -> 0 | H35: =SUMIF('Prior Invoice Log P1'!C:C,'Budget to Actual P1'!B35,'Prior Invoice Log P1'!G:G) -> 0 | I35: =SUMIF('Current Invoice Log P1'!C:C,'Budget to Actual P1'!B35,'Current Invoice Log P1'!G:G) -> 0 | J35: =SUM(H35,I35) -> 0 | K35: =IFERROR(J35/G35,0) -> 0 | L35: =+G35-J35 -> 0
C36: Zoning Variances Fees | D36: 0 | E36: 0 | F36: 0 | G36: =+D36+E36+F36 -> 0 | H36: =SUMIF('Prior Invoice Log P1'!C:C,'Budget to Actual P1'!B36,'Prior Invoice Log P1'!G:G) -> 0 | I36: =SUMIF('Current Invoice Log P1'!C:C,'Budget to Actual P1'!B36,'Current Invoice Log P1'!G:G) -> 0 | J36: =SUM(H36,I36) -> 0 | K36: =IFERROR(J36/G36,0) -> 0 | L36: =+G36-J36 -> 0
C37: Impact Fees - General | D37: 0 | E37: 0 | F37: 0 | G37: =+D37+E37+F37 -> 0 | H37: =SUMIF('Prior Invoice Log P1'!C:C,'Budget to Actual P1'!B37,'Prior Invoice Log P1'!G:G) -> 0 | I37: =SUMIF('Current Invoice Log P1'!C:C,'Budget to Actual P1'!B37,'Current Invoice Log P1'!G:G) -> 0 | J37: =SUM(H37,I37) -> 0 | K37: =IFERROR(J37/G37,0) -> 0 | L37: =+G37-J37 -> 0
C38: Impact Fees - Water | D38: 0 | E38: 0 | F38: 0 | G38: =+D38+E38+F38 -> 0 | H38: =SUMIF('Prior Invoice Log P1'!C:C,'Budget to Actual P1'!B38,'Prior Invoice Log P1'!G:G) -> 0 | I38: =SUMIF('Current Invoice Log P1'!C:C,'Budget to Actual P1'!B38,'Current Invoice Log P1'!G:G) -> 0 | J38: =SUM(H38,I38) -> 0 | K38: =IFERROR(J38/G38,0) -> 0 | L38: =+G38-J38 -> 0
C39: Impact Fees - Sewer | D39: 0 | E39: 0 | F39: 0 | G39: =+D39+E39+F39 -> 0 | H39: =SUMIF('Prior Invoice Log P1'!C:C,'Budget to Actual P1'!B39,'Prior Invoice Log P1'!G:G) -> 0 | I39: =SUMIF('Current Invoice Log P1'!C:C,'Budget to Actual P1'!B39,'Current Invoice Log P1'!G:G) -> 0 | J39: =SUM(H39,I39) -> 0 | K39: =IFERROR(J39/G39,0) -> 0 | L39: =+G39-J39 -> 0
C40: Impact Fees - Park | D40: 0 | E40: 0 | F40: 0 | G40: =+D40+E40+F40 -> 0 | H40: =SUMIF('Prior Invoice Log P1'!C:C,'Budget to Actual P1'!B40,'Prior Invoice Log P1'!G:G) -> 0 | I40: =SUMIF('Current Invoice Log P1'!C:C,'Budget to Actual P1'!B40,'Current Invoice Log P1'!G:G) -> 0 | J40: =SUM(H40,I40) -> 0 | K40: =IFERROR(J40/G40,0) -> 0 | L40: =+G40-J40 -> 0
... C43: Impact Fees - Other | D43: 0 | E43: 0 | F43: 0 | G43: =+D43+E43+F43 -> 0 | H43: =SUMIF('Prior Invoice Log P1'!C:C,'Budget to Actual P1'!B43,'Prior Invoice Log P1'!G:G) -> 0 | I43: =SUMIF('Current Invoice Log P1'!C:C,'Budget to Actual P1'!B43,'Current Invoice Log P1'!G:G) -> 0 | J43: =SUM(H43,I43) -> 0 | K43: =IFERROR(J43/G43,0) -> 0 | L43: =+G43-J43 -> 0
C44: Permits and Fees | D44: =SUBTOTAL(9,D29:D43) -> 0 | E44: =SUBTOTAL(9,E29:E43) -> 0 | F44: =SUBTOTAL(9,F29:F43) -> 0 | G44: =SUBTOTAL(9,G29:G43) -> 0 | H44: =SUBTOTAL(9,H29:H43) -> 0 | I44: =SUBTOTAL(9,I29:I43) -> 0 | J44: =SUBTOTAL(9,J29:J43) -> 0 | K44: =IFERROR(J44/G44,0) -> 0 | L44: =SUBTOTAL(9,L29:L43) -> 0
C45: Construction Management Fees | E45: 0 | F45: 0 | G45: =+D45+E45+F45 -> 0 | H45: =SUMIF('Prior Invoice Log P1'!C:C,'Budget to Actual P1'!B45,'Prior Invoice Log P1'!G:G) -> 0 | I45: =SUMIF('Current Invoice Log P1'!C:C,'Budget to Actual P1'!B45,'Current Invoice Log P1'!G:G) -> 0 | J45: =SUM(H45:I45) -> 0 | K45: =J45/G45 -> #DIV/0! | L45: =+G45-J45 -> 0
...

Sheet Soft Cost Contingency P1
B1: ='Budget to Actual P1'!B2 -> County Line Rail Silsbee LLC
B2: Soft Cost Contingency Table
B3: ='Budget to Actual P1'!B4 -> 46203
C6: Cost Category | D6: Contingency | E6: Contingency | F6: Contingency | G6: Req # | H6: Notes
D7: Previously | E7: Requested | F7: Total
B8: COA# | D8: Requested | E8: Herein | F8: Requested
B15: 11230-5 | C15: Electrical Improvements | D15: -540 | G15: 10 | H15: Budget adjustment
B16: 12230 | C16: Professional Services - Accounting | D16: 4239.34 | G16: 10 | H16: Budget overrun on accounting
B17: 12115 | C17: A&E | D17: 2868.08 | G17: 9 | H17: Budget overrun on A&E
B18: 12115 | C18: A&E | D18: 5802.86 | G18: 8 | H18: Budget overrun on A&E
B19: 11970 | C19: Legal | D19: 5560.42 | G19: 7 | H19: Budget overrun on Legal
B20: 12115 | C20: A&E | D20: 5000 | G20: 7 | H20: Budget overrun on A&E
B21: 12115 | C21: A&E | D21: 9943.8 | G21: 6 | H21: Budget overrun on A&E
B22: 12115 | C22: A&E | D22: 10781.62 | G22: 5 | H22: Budget overrun on A&E
C23: Total Other Development Costs | D23: =SUBTOTAL(9,D$9:D$22) -> 39956.78 | E23: =SUBTOTAL(9,E$9:E$22) -> 3699.34 | F23: =D23+E23 -> 43656.12
B26: Contingency Allocations | D26: =SUM(D23:D25) -> 39956.78 | E26: =SUM(E23:E25) -> 3699.34 | F26: =SUM(F23:F25) -> 43656.12
B28: Original Contingency Budget | D28: ='Budget to Actual P1'!D27 -> 293570.38
B30: Contingency Previously Requested | D30: =+D26 -> 39956.78
B31: Contingency Requested Herein | D31: =+E26 -> 3699.34
B32: Total Contingency Requested | D32: =+SUM(D30:D31) -> 43656.12
B34: Remaining Contingency | D34: =+$D$28-$D$32 -> 249914.26
D39: =ROUND(D34,2)=ROUND('Budget to Actual P1'!L27,2) -> TRUE | E39: Budget to Actual = Soft Cost Contingency Table

Sheet Soft cost contingency-PSTR
B4: Cost Category | C4: Contingency | D4: Contingency | E4: Contingency | F4: Req | G4: Notes
C5: Previously | D5: Requested | E5: Total
A6: COA# | C6: Requested | D6: Herein | E6: Requested
B14: Land | C14: 0.36 | F14: 1
B15: Due Diligence | C15: 1949.64 | F15: 1
B16: Total Other Development Costs | C16: =SUM(C7:C15) -> 1950 | D16: =SUM(D7:D15) -> 0 | E16: =C16+D16 -> 1950
A19: Contingency Allocations | C19: =SUM(C16:C18) -> 1950 | D19: =SUM(D16:D18) -> 0 | E19: =SUM(E16:E18) -> 1950
A21: Original Contingency Budget | C21: =#REF! -> #REF!
A23: Contingency Previously Requested | C23: =+C19 -> 1950
A24: Contingency Requested Herein | C24: =+D19 -> 0
A25: Total Contingency Requested | C25: =+SUM(C23:C24) -> 1950
A27: Remaining Contingency | C27: =+C21-C25 -> #REF!
C30: =C27-#REF! -> #REF!

Sheet Hard cost contingency
B4: Cost Category | C4: Contingency | D4: Contingency | E4: Req | F4: Notes
C5: Previously | D5: Requested
A6: COA# | C6: Requested | D6: Herein
J20: Reference Hidden Tab "Bridge Approvd Budget to Actual"
J21: Added 489,803.90 to Orginal Budget (1,914,611.10)
D29: 0
B30: Total Other Development Costs | C30: =SUM(C10:C29) -> 0 | D30: =SUM(D7:D29) -> 0
A33: Contingency Allocations | C33: =SUM(C30:C32) -> 0 | D33: =SUM(D30:D32) -> 0
A35: Original Contingency Budget | C35: ='Budget to Actual P1'!#REF! -> #REF!
A37: Contingency Previously Requested | C37: =+C33 -> 0
A38: Contingency Requested Herein | C38: =+D33 -> 0
A39: Total Contingency Requested | C39: =+SUM(C37:C38) -> 0
A41: Remaining Contingency | C41: =+C35-C39 -> #REF!
C45: =C41-'Budget to Actual P1'!#REF! -> #REF!

Sheet Hard Cost Contigency P1
B1: ='Budget to Actual P1'!B2 -> County Line Rail Silsbee LLC
B2: Hard Cost Contingency Table
B3: ='Budget to Actual P1'!B4 -> 46203
C6: Cost Category | D6: Contingency | E6: Contingency | F6: Contingency | G6: Req # | H6: Notes
D7: Previously | E7: Requested | F7: Total
B8: COA# | D8: Requested | E8: Herein | F8: Requested
K13: 0
B19: 11230-3 | C19: Sprinkler Improvements | D19: 16174 | G19: 10 | H19: Budget Reallocation
B20: 11230-7 | C20: Other Hard Costs | D20: 15561.43 | G20: 8 | H20: Budget Reallocation
B21: 11230-1 | C21: Yard Stabilization | D21: 48645.39 | G21: 7 | H21: Budget Reallocation
B22: 11230-4 | C22: Roof Improvements | D22: 300 | G22: 6 | H22: Budget Reallocation
B23: 11230-7 | C23: Other Hard Costs | D23: 12605.92 | G23: 6 | H23: Budget Reallocation
B24: 11230-7 | C24: Other Hard Costs | D24: 19200.94 | G24: 5 | H24: Budget Reallocation
B25: 11230-7 | C25: Other Hard Costs | D25: 109167.61 | G25: 4 | H25: Budget Reallocation
C26: Total Other Development Costs | D26: =SUBTOTAL(9,D$9:D$25) -> 205481.29 | E26: =SUBTOTAL(9,E$9:E$25) -> 16174 | F26: =D26+E26 -> 221655.29
B29: Contingency Allocations | D29: =SUM(D26:D28) -> 205481.29 | E29: =SUM(E26:E28) -> 16174 | F29: =SUM(F26:F28) -> 221655.29
B31: Original Contingency Budget | D31: ='Budget to Actual P1'!D26 -> 346282.8
B33: Contingency Previously Requested | D33: =+D29 -> 205481.29
B34: Contingency Requested Herein | D34: =+E29 -> 16174
B35: Total Contingency Requested | D35: =+SUM(D33:D34) -> 221655.29
B37: Remaining Contingency | D37: =+$D$31-$D$35 -> 124627.51
D41: =ROUND(D37,2)=ROUND('Budget to Actual P1'!L26,2) -> TRUE | E41: Budget to Actual = Hard Cost Contingency Table

Sheet Current Invoice Log P1
A1: ='Budget to Actual P1'!B2 -> County Line Rail Silsbee LLC
A2: Current Invoice Log
A3: ='Budget to Actual P1'!B4 -> 46203
A5: Cost Category | B5: Bank Cost Category | C5: Cost Code # | D5: Cost Code Name | E5: Vendor | F5: Bill number | G5: Amount | H5: Requisition Month | I5: Invoice (Y/N)
A6: Professional Services - Accounting | C6: 12230 | D6: Professional Services - Accounting | E6: CliftonLarsonAllen LLP | F6: L261457720 | G6: 6912.36 | H6: Req#11 | K6: 2026-07-27 | Y6: 12230
D8: Professional Services - Accounting Total | G8: =SUBTOTAL(9,G6:G7)
A10: Construction Period Interest | C10: 12321 | D10: Construction Period Interest | E10: BoTX | F10: Jul_26 Interest | G10: 62794.4 | H10: Req#11 | K10: 2026-07-13 | Y10: 12321
D12: Construction Period Interest Total | G12: =SUBTOTAL(9,G10:G11)
A14: Soft Costs | B14: Development Fee | C14: 12913 | D14: Development Fee | E14: County Line Rail Interest | F14: July_26 Dev Fee | G14: 10049.82 | H14: Req#11 | Y14: 12913
D16: Development Fee Total | G16: =SUBTOTAL(9,G14:G15)
A18: Broker Commissions | C18: 12594 | D18: Broker Commissions | E18: DFW Lee & Associates, LLC - Houston Office, RS | F18: 20256631-1 | G18: 181538.72 | H18: Req#11 | K18: 2026-07-01 | Y18: 12594
D20: Broker Commissions Total | G20: =SUBTOTAL(9,G18:G19)
D22: Grand Total | G22: =SUBTOTAL(9,G6:G21)

Sheet Prior Invoice Log P1
A1: ='Budget to Actual P1'!B2 -> County Line Rail Silsbee LLC
A2: Prior Invoice Log
A3: ='Budget to Actual P1'!B4 -> 46203
A5: Cost Category | B5: Bank Cost Category | C5: Cost Code # | D5: Cost Code Name | E5: Vendor | F5: Bill number | G5: Amount Paid | H5: Requisition Month | I5: Invoice
A6: Land Cost | C6: 11010 | D6: Acquisitions Costs (Land Purchase)
D8: Acquisitions Costs (Land Purchase) Total | G8: =SUBTOTAL(9,G6:G7)
A10: Construction Costs | C10: 11210 | D10: Expansion Costs (Base Construction Costs)
A11: Construction Costs | C11: 11210 | D11: Expansion Costs (Base Construction Costs)
D13: Expansion Costs (Base Construction Costs) Total | G13: =SUBTOTAL(9,G10:G12)
A15: Construction Cost | C15: 11212 | D15: Other Structures (BNSF 418 Road Crossing Install)
A16: Construction Cost | C16: 11212 | D16: Other Structures (BNSF 418 Road Crossing Install)
A17: Construction Cost | C17: 11212 | D17: Other Structures (BNSF 418 Road Crossing Install)
D19: Other Structures (BNSF 418 Road Crossing Install) Total | G19: =SUBTOTAL(9,G15:G18)
A21: Construction Cost | C21: 11213 | D21: Track Clearing Repair
A22: Construction Cost | C22: 11213 | D22: Track Clearing Repair
A23: Construction Cost | C23: 11213 | D23: Track Clearing Repair
D25: Track Clearing Repair Total | G25: =SUBTOTAL(9,G21:G24)
A27: Construction Costs | C27: 11214 | D27: Building Repair (waterproofing)
A28: Construction Costs | C28: 11214 | D28: Building Repair (waterproofing)
A29: Construction Cost | C29: 11214 | D29: Building Repair | G29: 0
D31: Building Repair (waterproofing) Total | G31: =SUBTOTAL(9,G27:G30)
A33: Construction Cost | C33: 11215 | D33: Deferred Maintenance
A34: Construction Cost | C34: 11215 | D34: Deferred Maintenance
A35: Construction Cost | C35: 11215 | D35: Deferred Maintenance
D37: Base Construction Costs Total | G37: =SUBTOTAL(9,G33:G36)
A39: Construction Cost | C39: 11218 | D39: Working Capital
A40: Construction Cost | C40: 11218 | D40: Working Capital
D42: Working Capital Total | G42: =SUBTOTAL(9,G39:G41)
A44: Design and Engineering Consultants | C44: 12115 | D44: A&E
A45: Design and Engineering Consultants | C45: 12115 | D45: A&E
A46: Design and Engineering Consultants | C46: 12115 | D46: A&E | E46: TRC | F46: 50631
A47: Appraisal | C47: 12115 | D47: Appraisal | E47: Colliers International
A48: Appraisal | C48: 12115 | D48: Appraisal | E48: Colliers International
D50: A&E Total | G50: =SUBTOTAL(9,G44:G49)
A52: Design and Engineering Consultants | C52: 12116 | D52: Environmental
A53: Design and Engineering Consultants | C53: 12116 | D53: Environmental
A54: Design and Engineering Consultants | C54: 12116 | D54: Environmental
D56: Environmental Total | G56: =SUBTOTAL(9,G52:G55)
A58: Other Construction Costs | C58: 11230-1 | D58: Other Construction Costs | E58: Agri-Serv Industrial Maintenance | F58: Pay App#1 | G58: 142534.8 | H58: Rec #1
A59: Other Construction Costs | C59: 11230-2 | D59: Other Construction Costs | E59: Stewart Development & Construction, LLC | F59: Pay App#1 | G59: 110286.65 | H59: Rec #1
...

Sheet Dev Fee P1
A2: County Line Rail Silsbee
A3: Development Fee Calculation
A4: 46203
B6: Project costs | C6: Project costs | D6: Project costs
B7: Incurred to date | C7: Incurred - Month of | D7: Incurred
B8: 46203 | C8: =B8 -> 46203 | D8: 46173
A9: Project costs
A10: Hard Costs | B10: ='Budget to Actual P1'!J28 -> 5467355.1 | C10: ='Budget to Actual P1'!I28 -> 182172.28 | D10: =B10-C10 -> 5285182.9
A11: Soft Costs | B11: ='Budget to Actual P1'!J67+'Budget to Actual P1'!J92+'Budget to Actual P1'!J124 -> 1817226.6 | C11: ='Budget to Actual P1'!I67+'Budget to Actual P1'!I92+'Budget to Actual P1'!I124 -> 71320.52 | D11: =B11-C11 -> 1745906.1
D12: =B12-C12 -> 0
A13: Total | B13: =SUM($B$10:$B$12) -> 7284581.7 | C13: =SUM(C10:C12) -> 253492.8 | D13: =SUM($D$10:$D$12) -> 7031088.9
A14: Total per GL
A15: Discrepancy | B15: =B13-B14 -> 7284581.7
A17: Development fees: | B17: Dev fees incurred to date | C17: Current Month Dev Fee | D17: Prior Month Balance
A18: Due to CLR Silsbee Property Owner | B18: =ROUND(B13*0.04,2) -> 291383.27 | C18: =C13*0.04 -> 10139.712 | D18: =ROUND($D$13*0.04,2) -> 281243.56
A19: Total: | B19: =SUM(B18:B18) -> 291383.27 | C19: =C14*0.04 -> 0 | D19: =SUM($D$18:$D$18) -> 281243.56
B25: Total | C25: =C18 -> 10139.712

Sheet Project Costs (Dev)

Sheet OP->

Sheet Budget to Actual (OP)
C2: PROJECT FUNDING REQUISITION
C3: County Line Rail Silsbee LLC
C4: Application Period: 12/31/2025
C5: Requisition Report #17
C7: Operations | D7: Silsbee PO | E7: Previous Contingency | F7: Current Contingency | G7: Silsbee PO | H7: Previous Application | I7: Payment this period | J7: Total Complete & Draw To Date | L7: Balance remaining
B8: GL Coding | C8: Account Name | D8: Approved Budget | E8: Funding & Reallocation | F8: Funding & Reallocation | G8: Current Approved Budget | H8: Inception to 11/30/2025 | I8: 46022 | J8: Incurred to 12/31/2025 | K8: Percent Drawn | L8: As of 12/31/2025
B10: 40120 | C10: In & Out Fees | D10: 303525 | E10: 0 | F10: 0 | G10: =ROUND(D10+E10+F10,2) -> 303525 | H10: =ROUND(SUMIF('Prior Revenue Log (OP)'!B:B,'Budget to Actual (OP)'!C10,'Prior Revenue Log (OP)'!G:G),2) -> 66483 | I10: =ROUND(SUMIF('Current Revenue Log (OP)'!B:B,'Budget to Actual (OP)'!C10,'Current Revenue Log (OP)'!G:G),2) -> 0 | J10: =ROUND(SUM(H10:I10),2) -> 66483 | K10: =IFERROR(J10/G10,0) -> 0.21903632 | L10: =ROUND(+G10-J10,2) -> 237042
B11: 40130 | C11: Storage Fees | D11: 681507.2 | E11: 0 | F11: 0 | G11: =ROUND(D11+E11+F11,2) -> 681507.2 | H11: =ROUND(SUMIF('Prior Revenue Log (OP)'!B:B,'Budget to Actual (OP)'!C11,'Prior Revenue Log (OP)'!G:G),2) -> 588015 | I11: =ROUND(SUMIF('Current Revenue Log (OP)'!B:B,'Budget to Actual (OP)'!C11,'Current Revenue Log (OP)'!G:G),2) -> 0 | J11: =ROUND(SUM(H11:I11),2) -> 588015 | K11: =IFERROR(J11/G11,0) -> 0.86281554 | L11: =ROUND(+G11-J11,2) -> 93492.2
B12: 40140 | C12: Transloading Fees | D12: 0 | E12: 0 | F12: 0 | G12: =ROUND(D12+E12+F12,2) -> 0 | H12: =ROUND(SUMIF('Prior Revenue Log (OP)'!B:B,'Budget to Actual (OP)'!C12,'Prior Revenue Log (OP)'!G:G),2) -> 0 | I12: =ROUND(SUMIF('Current Revenue Log (OP)'!B:B,'Budget to Actual (OP)'!C12,'Current Revenue Log (OP)'!G:G),2) -> 0 | J12: =ROUND(SUM(H12:I12),2) -> 0 | K12: =IFERROR(J12/G12,0) -> 0 | L12: =ROUND(+G12-J12,2) -> 0
B13: 40160 | C13: Intra Plant Switch Fees | D13: 0 | E13: 0 | F13: 0 | G13: =ROUND(D13+E13+F13,2) -> 0 | H13: =ROUND(SUMIF('Prior Revenue Log (OP)'!B:B,'Budget to Actual (OP)'!C13,'Prior Revenue Log (OP)'!G:G),2) -> 0 | I13: =ROUND(SUMIF('Current Revenue Log (OP)'!B:B,'Budget to Actual (OP)'!C13,'Current Revenue Log (OP)'!G:G),2) -> 0 | J13: =ROUND(SUM(H13:I13),2) -> 0 | K13: =IFERROR(J13/G13,0) -> 0 | L13: =ROUND(+G13-J13,2) -> 0
B14: 40400 | C14: Concessions | D14: 0 | E14: 0 | F14: 0 | G14: =ROUND(D14+E14+F14,2) -> 0 | H14: =ROUND(SUMIF('Prior Revenue Log (OP)'!B:B,'Budget to Actual (OP)'!C14,'Prior Revenue Log (OP)'!G:G),2) -> 0 | I14: =ROUND(SUMIF('Current Revenue Log (OP)'!B:B,'Budget to Actual (OP)'!C14,'Current Revenue Log (OP)'!G:G),2) -> 0 | J14: =ROUND(SUM(H14:I14),2) -> 0 | K14: =IFERROR(J14/G14,0) -> 0 | L14: =ROUND(+G14-J14,2) -> 0
B15: 40451 | C15: Bad Debt | D15: 0 | E15: 0 | F15: 0 | G15: =ROUND(D15+E15+F15,2) -> 0 | H15: =ROUND(SUMIF('Prior Revenue Log (OP)'!B:B,'Budget to Actual (OP)'!C15,'Prior Revenue Log (OP)'!G:G),2) -> 0 | I15: =ROUND(SUMIF('Current Revenue Log (OP)'!B:B,'Budget to Actual (OP)'!C15,'Current Revenue Log (OP)'!G:G),2) -> 0 | J15: =ROUND(SUM(H15:I15),2) -> 0 | K15: =IFERROR(J15/G15,0) -> 0 | L15: =ROUND(+G15-J15,2) -> 0
C17: Total Rail Income | D17: =ROUND(SUBTOTAL(9,D10:D16),2) -> 985032.2 | E17: =ROUND(SUBTOTAL(9,E10:E16),2) -> 0 | F17: =ROUND(SUBTOTAL(9,F10:F16),2) -> 0 | G17: =ROUND(SUBTOTAL(9,G10:G16),2) -> 985032.2 | H17: =ROUND(SUBTOTAL(9,H10:H16),2) -> 654498 | I17: =ROUND(SUBTOTAL(9,I10:I16),2) -> 0 | J17: =ROUND(SUBTOTAL(9,J10:J16),2) -> 654498 | K17: =ROUND(SUBTOTAL(9,K10:K16),2) -> 1.08 | L17: =ROUND(SUBTOTAL(9,L10:L16),2) -> 330534.2
B18: 40110 | C18: Short Term Land Leases | D18: 138000 | E18: 0 | F18: 0 | G18: =ROUND(D18+E18+F18,2) -> 138000 | H18: =ROUND(SUMIF('Prior Revenue Log (OP)'!B:B,'Budget to Actual (OP)'!C18,'Prior Revenue Log (OP)'!G:G),2) -> 130360 | I18: =ROUND(SUMIF('Current Revenue Log (OP)'!B:B,'Budget to Actual (OP)'!C18,'Current Revenue Log (OP)'!G:G),2) -> 0 | J18: =ROUND(SUM(H18:I18),2) -> 130360 | K18: =IFERROR(J18/G18,0) -> 0.94463768 | L18: =ROUND(+G18-J18,2) -> 7640
B19: 40140 | C19: Intra-Plant Switch Fees | D19: 0 | E19: 0 | F19: 0 | G19: =ROUND(D19+E19+F19,2) -> 0 | H19: =ROUND(SUMIF('Prior Revenue Log (OP)'!B:B,'Budget to Actual (OP)'!C19,'Prior Revenue Log (OP)'!G:G),2) -> 0 | I19: =ROUND(SUMIF('Current Revenue Log (OP)'!B:B,'Budget to Actual (OP)'!C19,'Current Revenue Log (OP)'!G:G),2) -> 0 | J19: =ROUND(SUM(H19:I19),2) -> 0 | K19: =IFERROR(J19/G19,0) -> 0 | L19: =ROUND(+G19-J19,2) -> 0
B20: 40150 | C20: Warehouse Lease Income | D20: 700000 | E20: 0 | F20: 0 | G20: =ROUND(D20+E20+F20,2) -> 700000 | H20: =ROUND(SUMIF('Prior Revenue Log (OP)'!B:B,'Budget to Actual (OP)'!C20,'Prior Revenue Log (OP)'!G:G),2) -> 200000 | I20: =ROUND(SUMIF('Current Revenue Log (OP)'!B:B,'Budget to Actual (OP)'!C20,'Current Revenue Log (OP)'!G:G),2) -> 0 | J20: =ROUND(SUM(H20:I20),2) -> 200000 | K20: =IFERROR(J20/G20,0) -> 0.28571429 | L20: =ROUND(+G20-J20,2) -> 500000
B21: 40160 | C21: Transloading Fees | D21: 0 | E21: 0 | F21: 0 | G21: =ROUND(D21+E21+F21,2) -> 0 | H21: =ROUND(SUMIF('Prior Revenue Log (OP)'!B:B,'Budget to Actual (OP)'!C21,'Prior Revenue Log (OP)'!G:G),2) -> 0 | I21: =ROUND(SUMIF('Current Revenue Log (OP)'!B:B,'Budget to Actual (OP)'!C21,'Current Revenue Log (OP)'!G:G),2) -> 0 | J21: =ROUND(SUM(H21:I21),2) -> 0 | K21: =IFERROR(J21/G21,0) -> 0 | L21: =ROUND(+G21-J21,2) -> 0
B22: 41114 | C22: Late Fees | D22: 0 | E22: 0 | F22: 0 | G22: =ROUND(D22+E22+F22,2) -> 0 | H22: =ROUND(SUMIF('Prior Revenue Log (OP)'!B:B,'Budget to Actual (OP)'!C22,'Prior Revenue Log (OP)'!G:G),2) -> 0 | I22: =ROUND(SUMIF('Current Revenue Log (OP)'!B:B,'Budget to Actual (OP)'!C22,'Current Revenue Log (OP)'!G:G),2) -> 0 | J22: =ROUND(SUM(H22:I22),2) -> 0 | K22: =IFERROR(J22/G22,0) -> 0 | L22: =ROUND(+G22-J22,2) -> 0
C24: Total Other Income | D24: =ROUND(SUBTOTAL(9,D18:D23),2) -> 838000 | E24: =ROUND(SUBTOTAL(9,E18:E23),2) -> 0 | F24: =ROUND(SUBTOTAL(9,F18:F23),2) -> 0 | G24: =ROUND(SUBTOTAL(9,G18:G23),2) -> 838000 | H24: =ROUND(SUBTOTAL(9,H18:H23),2) -> 330360 | I24: =ROUND(SUBTOTAL(9,I18:I23),2) -> 0 | J24: =ROUND(SUBTOTAL(9,J18:J23),2) -> 330360 | K24: =IFERROR(J24/G24,0) -> 0.39422434 | L24: =ROUND(SUBTOTAL(9,L18:L23),2) -> 507640
C26: Total Income | D26: =ROUND(SUBTOTAL(9,D9:D25),2) -> 1823032.2 | E26: =ROUND(SUBTOTAL(9,E9:E25),2) -> 0 | F26: =ROUND(SUBTOTAL(9,F9:F25),2) -> 0 | G26: =ROUND(SUBTOTAL(9,G9:G25),2) -> 1823032.2 | H26: =ROUND(SUBTOTAL(9,H9:H25),2) -> 984858 | I26: =ROUND(SUBTOTAL(9,I9:I25),2) -> 0 | J26: =ROUND(SUBTOTAL(9,J9:J25),2) -> 984858 | K26: =IFERROR(J26/G26,0) -> 0.54023072 | L26: =ROUND(SUBTOTAL(9,L9:L25),2) -> 838174.2
B27: 63034 | C27: Switchmen Salaries - Reimbursable | D27: 147792.69 | E27: 0 | F27: 0 | G27: =ROUND(D27+E27+F27,2) -> 147792.69 | H27: =ROUND(SUMIF('Prior Invoice Log (OP)'!B:B,'Budget to Actual (OP)'!C27,'Prior Invoice Log (OP)'!H:H),2) -> 163556.67 | I27: =ROUND(SUMIF('Current Invoice Log (OP)'!B:B,C27,'Current Invoice Log (OP)'!H:H),2) -> 11560.34 | J27: =ROUND(SUM(H27:I27),2) -> 175117.01 | K27: =IFERROR(J27/G27,0) -> 1.1848828 | L27: =ROUND(+G27-J27,2) -> -27324.32
B28: 63032 | C28: Switchmen Healthcare – Reimbursable | D28: 0 | E28: 0 | F28: 0 | G28: =ROUND(D28+E28+F28,2) -> 0 | H28: =ROUND(SUMIF('Prior Invoice Log (OP)'!B:B,'Budget to Actual (OP)'!C28,'Prior Invoice Log (OP)'!H:H),2) -> 0 | I28: =ROUND(SUMIF('Current Invoice Log (OP)'!B:B,C28,'Current Invoice Log (OP)'!H:H),2) -> 0 | J28: =ROUND(SUM(H28:I28),2) -> 0 | K28: =IFERROR(J28/G28,0) -> 0 | L28: =ROUND(+G28-J28,2) -> 0
B29: 63033 | C29: Mowing Assistance - Reimbursable | D29: 36000 | E29: 0 | F29: 0 | G29: =ROUND(D29+E29+F29,2) -> 36000 | H29: =ROUND(SUMIF('Prior Invoice Log (OP)'!B:B,'Budget to Actual (OP)'!C29,'Prior Invoice Log (OP)'!H:H),2) -> 17150 | I29: =ROUND(SUMIF('Current Invoice Log (OP)'!B:B,C29,'Current Invoice Log (OP)'!H:H),2) -> 0 | J29: =ROUND(SUM(H29:I29),2) -> 17150 | K29: =IFERROR(J29/G29,0) -> 0.47638889 | L29: =ROUND(+G29-J29,2) -> 18850
B30: 63041 | C30: Onsite Manager | D30: 101165.26 | E30: 0 | F30: 0 | G30: =ROUND(D30+E30+F30,2) -> 101165.26 | H30: =ROUND(SUMIF('Prior Invoice Log (OP)'!B:B,'Budget to Actual (OP)'!C30,'Prior Invoice Log (OP)'!H:H),2) -> 0 | I30: =ROUND(SUMIF('Current Invoice Log (OP)'!B:B,C30,'Current Invoice Log (OP)'!H:H),2) -> 0 | J30: =ROUND(SUM(H30:I30),2) -> 0 | K30: =IFERROR(J30/G30,0) -> 0 | L30: =ROUND(+G30-J30,2) -> 101165.26
B31: 63042 | C31: Overtime | D31: 18000 | E31: 0 | F31: 0 | G31: =ROUND(D31+E31+F31,2) -> 18000 | H31: =ROUND(SUMIF('Prior Invoice Log (OP)'!B:B,'Budget to Actual (OP)'!C31,'Prior Invoice Log (OP)'!H:H),2) -> 0 | I31: =ROUND(SUMIF('Current Invoice Log (OP)'!B:B,C31,'Current Invoice Log (OP)'!H:H),2) -> 0 | J31: =ROUND(SUM(H31:I31),2) -> 0 | K31: =IFERROR(J31/G31,0) -> 0 | L31: =ROUND(+G31-J31,2) -> 18000
B32: 64000 | C32: Security | D32: 80004 | E32: 0 | F32: 0 | G32: =ROUND(D32+E32+F32,2) -> 80004 | H32: =ROUND(SUMIF('Prior Invoice Log (OP)'!B:B,'Budget to Actual (OP)'!C32,'Prior Invoice Log (OP)'!H:H),2) -> 82034.61 | I32: =ROUND(SUMIF('Current Invoice Log (OP)'!B:B,C32,'Current Invoice Log (OP)'!H:H),2) -> 6245.3 | J32: =ROUND(SUM(H32:I32),2) -> 88279.91 | K32: =IFERROR(J32/G32,0) -> 1.1034437 | L32: =ROUND(+G32-J32,2) -> -8275.91
B33: 63028 | C33: Asset Manager - (County Line) | D33: 22500 | E33: 0 | F33: 0 | G33: =ROUND(D33+E33+F33,2) -> 22500 | H33: =ROUND(SUMIF('Prior Invoice Log (OP)'!B:B,'Budget to Actual (OP)'!C33,'Prior Invoice Log (OP)'!H:H),2) -> 13125 | I33: =ROUND(SUMIF('Current Invoice Log (OP)'!B:B,C33,'Current Invoice Log (OP)'!H:H),2) -> 0 | J33: =ROUND(SUM(H33:I33),2) -> 13125 | K33: =IFERROR(J33/G33,0) -> 0.58333333 | L33: =ROUND(+G33-J33,2) -> 9375
B34: 63036 | C34: Accounting (County Line) | D34: 22500 | E34: 0 | F34: 0 | G34: =ROUND(D34+E34+F34,2) -> 22500 | H34: =ROUND(SUMIF('Prior Invoice Log (OP)'!B:B,'Budget to Actual (OP)'!C34,'Prior Invoice Log (OP)'!H:H),2) -> 13125 | I34: =ROUND(SUMIF('Current Invoice Log (OP)'!B:B,C34,'Current Invoice Log (OP)'!H:H),2) -> 0 | J34: =ROUND(SUM(H34:I34),2) -> 13125 | K34: =IFERROR(J34/G34,0) -> 0.58333333 | L34: =ROUND(+G34-J34,2) -> 9375
B35: 63040 | C35: Business Development (County Line) | D35: 60000 | E35: 0 | F35: 0 | G35: =ROUND(D35+E35+F35,2) -> 60000 | H35: =ROUND(SUMIF('Prior Invoice Log (OP)'!B:B,'Budget to Actual (OP)'!C35,'Prior Invoice Log (OP)'!H:H),2) -> 35000 | I35: =ROUND(SUMIF('Current Invoice Log (OP)'!B:B,C35,'Current Invoice Log (OP)'!H:H),2) -> 0 | J35: =ROUND(SUM(H35:I35),2) -> 35000 | K35: =IFERROR(J35/G35,0) -> 0.58333333 | L35: =ROUND(+G35-J35,2) -> 25000
B36: 63041 | C36: Offsite Manager | D36: 0 | E36: 0 | F36: 0 | G36: =ROUND(D36+E36+F36,2) -> 0 | H36: =ROUND(SUMIF('Prior Invoice Log (OP)'!B:B,'Budget to Actual (OP)'!C36,'Prior Invoice Log (OP)'!H:H),2) -> 18592.12 | I36: =ROUND(SUMIF('Current Invoice Log (OP)'!B:B,C36,'Current Invoice Log (OP)'!H:H),2) -> -1603.53 | J36: =ROUND(SUM(H36:I36),2) -> 16988.59 | K36: =IFERROR(J36/G36,0) -> 0 | L36: =ROUND(+G36-J36,2) -> -16988.59
B37: 63042 | C37: Offsite Staff | D37: 0 | E37: 0 | F37: 0 | G37: =ROUND(D37+E37+F37,2) -> 0 | H37: =ROUND(SUMIF('Prior Invoice Log (OP)'!B:B,'Budget to Actual (OP)'!C37,'Prior Invoice Log (OP)'!H:H),2) -> 51130.03 | I37: =ROUND(SUMIF('Current Invoice Log (OP)'!B:B,C37,'Current Invoice Log (OP)'!H:H),2) -> 10116.6 | J37: =ROUND(SUM(H37:I37),2) -> 61246.63 | K37: =IFERROR(J37/G37,0) -> 0 | L37: =ROUND(+G37-J37,2) -> -61246.63 | M37: <-- Non-Budgeted Item
C39: Total Payroll | D39: =ROUND(SUBTOTAL(9,D27:D38),2) -> 487961.95 | E39: =ROUND(SUBTOTAL(9,E27:E38),2) -> 0 | F39: =ROUND(SUBTOTAL(9,F27:F38),2) -> 0 | G39: =ROUND(SUBTOTAL(9,G27:G38),2) -> 487961.95 | H39: =ROUND(SUBTOTAL(9,H27:H38),2) -> 393713.43 | I39: =ROUND(SUBTOTAL(9,I27:I38),2) -> 26318.71 | J39: =ROUND(SUBTOTAL(9,J27:J38),2) -> 420032.14 | K39: =IFERROR(J39/G39,0) -> 0.86078872 | L39: =ROUND(SUBTOTAL(9,L27:L38),2) -> 67929.81
B40: 63025 | C40: Professional Fees | D40: 0 | E40: 0 | F40: 0 | G40: =ROUND(D40+E40+F40,2) -> 0 | H40: =ROUND(SUMIF('Prior Invoice Log (OP)'!B:B,'Budget to Actual (OP)'!C40,'Prior Invoice Log (OP)'!H:H),2) -> 7141.37 | I40: =ROUND(SUMIF('Current Invoice Log (OP)'!B:B,C40,'Current Invoice Log (OP)'!H:H),2) -> 1.25 | J40: =ROUND(SUM(H40:I40),2) -> 7142.62 | K40: =IFERROR(J40/G40,0) -> 0 | L40: =ROUND(+G40-J40,2) -> -7142.62 | M40: <-- Non-Budgeted Item
B41: 63050 | C41: Legal Fees | D41: 18000 | E41: 0 | F41: 0 | G41: =ROUND(D41+E41+F41,2) -> 18000 | H41: =ROUND(SUMIF('Prior Invoice Log (OP)'!B:B,'Budget to Actual (OP)'!C41,'Prior Invoice Log (OP)'!H:H),2) -> 66630.31 | I41: =ROUND(SUMIF('Current Invoice Log (OP)'!B:B,C41,'Current Invoice Log (OP)'!H:H),2) -> 0 | J41: =ROUND(SUM(H41:I41),2) -> 66630.31 | K41: =IFERROR(J41/G41,0) -> 3.7016839 | L41: =ROUND(+G41-J41,2) -> -48630.31
B42: 63100 | C42: Consulting Fees | D42: 10000 | E42: 0 | F42: 0 | G42: =ROUND(D42+E42+F42,2) -> 10000 | H42: =ROUND(SUMIF('Prior Invoice Log (OP)'!B:B,'Budget to Actual (OP)'!C42,'Prior Invoice Log (OP)'!H:H),2) -> 17876.26 | I42: =ROUND(SUMIF('Current Invoice Log (OP)'!B:B,C42,'Current Invoice Log (OP)'!H:H),2) -> 0 | J42: =ROUND(SUM(H42:I42),2) -> 17876.26 | K42: =IFERROR(J42/G42,0) -> 1.787626 | L42: =ROUND(+G42-J42,2) -> -7876.26
B43: 67100 | C43: Dues & Subscriptions | D43: 0 | E43: 0 | F43: 0 | G43: =ROUND(D43+E43+F43,2) -> 0 | H43: =ROUND(SUMIF('Prior Invoice Log (OP)'!B:B,'Budget to Actual (OP)'!C43,'Prior Invoice Log (OP)'!H:H),2) -> 1560 | I43: =ROUND(SUMIF('Current Invoice Log (OP)'!B:B,C43,'Current Invoice Log (OP)'!H:H),2) -> 0 | J43: =ROUND(SUM(H43:I43),2) -> 1560 | K43: =IFERROR(J43/G43,0) -> 0 | L43: =ROUND(+G43-J43,2) -> -1560
B44: 67200 | C44: Office Expense | D44: 12000 | E44: 0 | F44: 0 | G44: =ROUND(D44+E44+F44,2) -> 12000 | H44: =ROUND(SUMIF('Prior Invoice Log (OP)'!B:B,'Budget to Actual (OP)'!C44,'Prior Invoice Log (OP)'!H:H),2) -> 3099.65 | I44: =ROUND(SUMIF('Current Invoice Log (OP)'!B:B,C44,'Current Invoice Log (OP)'!H:H),2) -> 366.67 | J44: =ROUND(SUM(H44:I44),2) -> 3466.32 | K44: =IFERROR(J44/G44,0) -> 0.28886 | L44: =ROUND(+G44-J44,2) -> 8533.68
B45: 67250 | C45: Postage and Delivery | D45: 600 | E45: 0 | F45: 0 | G45: =ROUND(D45+E45+F45,2) -> 600 | H45: =ROUND(SUMIF('Prior Invoice Log (OP)'!B:B,'Budget to Actual (OP)'!C45,'Prior Invoice Log (OP)'!H:H),2) -> 0 | I45: =ROUND(SUMIF('Current Invoice Log (OP)'!B:B,C45,'Current Invoice Log (OP)'!H:H),2) -> 0 | J45: =ROUND(SUM(H45:I45),2) -> 0 | K45: =IFERROR(J45/G45,0) -> 0 | L45: =ROUND(+G45-J45,2) -> 600
B46: 67300 | C46: Telephone & Internet | D46: 1200 | E46: 0 | F46: 0 | G46: =ROUND(D46+E46+F46,2) -> 1200 | H46: =ROUND(SUMIF('Prior Invoice Log (OP)'!B:B,'Budget to Actual (OP)'!C46,'Prior Invoice Log (OP)'!H:H),2) -> 0 | I46: =ROUND(SUMIF('Current Invoice Log (OP)'!B:B,C46,'Current Invoice Log (OP)'!H:H),2) -> 0 | J46: =ROUND(SUM(H46:I46),2) -> 0 | K46: =IFERROR(J46/G46,0) -> 0 | L46: =ROUND(+G46-J46,2) -> 1200
B47: 67400 | C47: Advertising & Marketing | D47: 12000 | E47: 0 | F47: 0 | G47: =ROUND(D47+E47+F47,2) -> 12000 | H47: =ROUND(SUMIF('Prior Invoice Log (OP)'!B:B,'Budget to Actual (OP)'!C47,'Prior Invoice Log (OP)'!H:H),2) -> 0 | I47: =ROUND(SUMIF('Current Invoice Log (OP)'!B:B,C47,'Current Invoice Log (OP)'!H:H),2) -> 0 | J47: =ROUND(SUM(H47:I47),2) -> 0 | K47: =IFERROR(J47/G47,0) -> 0 | L47: =ROUND(+G47-J47,2) -> 12000
...

Sheet Current Revenue Log (OP)
B2: Cost Category | C2: Cost Code # | D2: Cost Code Name | E2: Customer | F2: Invoice # | G2: Amount Paid | H2: Requisition Month | I2: Invoice Date | K2: CURRENT REQ REPORT | L2: DUPLICATE(S)
B4: Short Term Land Leases | C4: 40110 | D4: Land Leases
B5: Short Term Land Leases | C5: 40110 | D5: Land Leases | E5: Utility Lines Construction Services | F5: 1415
D7: Land Leases Total | G7: =SUBTOTAL(9,G4:G6) -> 0
B9: In & Out Fees | C9: 40120 | D9: In & Out Fees
B10: In & Out Fees | C10: 40120 | D10: In & Out Fees
D12: In & Out Fees Total | G12: =SUBTOTAL(9,G9:G11) -> 0
B14: Storage Fees | C14: 40130 | D14: Storage Fees
B15: Storage Fees | C15: 40130 | D15: Storage Fees
D17: Storage Fees Total | G17: =SUBTOTAL(9,G14:G16) -> 0
B19: Trasnloading Fees | C19: 40140 | D19: Transloading | E19: Trecora Resources
D21: Transloading Total | G21: =SUBTOTAL(9,G19:G20) -> 0
B23: Warehouse Lease Income | C23: 40150 | D23: Warehouse Lease | E23: Louisiana-Pacific Corporation
D25: Warehouse Lease Total | G25: =SUBTOTAL(9,G23:G24) -> 0
D27: Grand Total | G27: =SUBTOTAL(9,G4:G26) -> 0

Sheet Prior Revenue Log (OP)
B2: Cost Category | C2: Cost Code # | D2: Cost Code Name | E2: Customer | F2: Invoice # | G2: Amount Paid | H2: Requisition Month | I2: Invoice Date | K2: CURRENT REQ REPORT | L2: DUPLICATE(S)
B4: Short Term Land Leases | C4: 40110 | D4: Land Leases | E4: Silsbee Ford | F4: 1303 | G4: 6500 | H4: 45658 | I4: 45689
B5: Short Term Land Leases | C5: 40110 | D5: Land Leases | E5: Utility Lines Construction Services | F5: 1405 | G5: 4500 | H5: 45658 | I5: 45689
B6: Short Term Land Leases | C6: 40110 | D6: Land Leases | E6: Silsbee Ford | F6: 1404 | G6: 6760 | H6: 45689 | I6: 45720 | M6: GL | N6: GL Term | O6: Invoice Term
B7: Short Term Land Leases | C7: 40110 | D7: Land Leases | E7: Utility Lines Construction Services | F7: 1406 | G7: 4500 | H7: 45689 | I7: 45720 | M7: 40110 | N7: Short Term Land Leases | O7: Rent - Short Term
B8: Short Term Land Leases | C8: 40110 | D8: Land Leases | E8: Silsbee Ford | F8: 1405 | G8: 6760 | H8: 45717 | I8: 45748 | M8: 40120 | N8: In & Out Fees | O8: Inbound/Outbound Fees
B9: Short Term Land Leases | C9: 40110 | D9: Land Leases | E9: Utility Lines Construction Services | F9: 1407 | G9: 4500 | H9: 45717 | I9: 45748 | M9: 40130 | N9: Storage Fees | O9: Warehouse Storage, Base Spots, Overages
B10: Short Term Land Leases | C10: 40110 | D10: Land Leases | E10: Silsbee Ford | F10: 1506 | G10: 6760 | H10: 45748 | I10: 45778 | M10: 40140 | N10: Intra-Plant Switch Fees | O10: Intra-Plant Switch Fees
B11: Short Term Land Leases | C11: 40110 | D11: Land Leases | E11: Utility Lines Construction Services | F11: 1408 | G11: 4500 | H11: 45748 | I11: 45778 | M11: 40150 | N11: Warehouse Lease Income | O11: Rent - Long term - Louisiana-Pacific
B12: Short Term Land Leases | C12: 40110 | D12: Land Leases | E12: Silsbee Ford | F12: 1507 | G12: 6760 | H12: 45802 | I12: 45809 | M12: 40160 | N12: Transloading Fees | O12: Transloading Fees
B13: Short Term Land Leases | C13: 40110 | D13: Land Leases | E13: Utility Lines Construction Services | F13: 1409 | G13: 4500 | H13: 45802 | I13: 45809
B14: Short Term Land Leases | C14: 40110 | D14: Land Leases | E14: Silsbee Ford | F14: 1508 | G14: 6760 | H14: 45833 | I14: 45840
B15: Short Term Land Leases | C15: 40110 | D15: Land Leases | E15: Utility Lines Construction Services | F15: 1411 | G15: 4500 | H15: 45833 | I15: 45840
B16: Short Term Land Leases | C16: 40110 | D16: Land Leases | E16: Silsbee Ford | F16: 1509 | G16: 6760 | H16: 45863 | I16: 45869
B17: Short Term Land Leases | C17: 40110 | D17: Land Leases | E17: Utility Lines Construction Services | F17: 1411 | G17: 4500 | H17: 45863 | I17: 45869
B18: Short Term Land Leases | C18: 40110 | D18: Land Leases | E18: Silsbee Ford | F18: 1510 | G18: 6760 | H18: 45894 | I18: 45900
B19: Short Term Land Leases | C19: 40110 | D19: Land Leases | E19: Utility Lines Construction Services | F19: 1412 | G19: 4500 | H19: 45894 | I19: 45900
B20: Short Term Land Leases | C20: 40110 | D20: Land Leases | E20: Silsbee Ford | F20: 1511 | G20: 6760 | H20: 45901 | I20: 45930
B21: Short Term Land Leases | C21: 40110 | D21: Land Leases | E21: Utility Lines Construction Services | F21: 1413 | G21: 4500 | H21: 45901 | I21: 45930
B22: Short Term Land Leases | C22: 40110 | D22: Land Leases | E22: Silsbee Ford | F22: 1512 | G22: 6760 | H22: 45931 | I22: 45961
B23: Short Term Land Leases | C23: 40110 | D23: Land Leases | E23: Utility Lines Construction Services | F23: 1414 | G23: 4500 | H23: 45931 | I23: 45961
B24: Short Term Land Leases | C24: 40110 | D24: Land Leases | E24: Silsbee Ford | F24: 1513 | G24: 6760 | H24: 45986 | I24: 45991
B25: Short Term Land Leases | C25: 40110 | D25: Land Leases | E25: Utility Lines Construction Services | F25: 1415 | G25: 4500 | H25: 45986 | I25: 45991
B26: Short Term Land Leases | C26: 40110 | D26: Land Leases | E26: Silsbee Ford | F26: 1514 | G26: 6760 | H26: 45992 | I26: 45992
D28: Land Leases Total | G28: =SUBTOTAL(9,G4:G27) -> 130360
B30: In & Out Fees | C30: 40120 | D30: In & Out Fees | E30: Trecora Recources | F30: 1304 | G30: 440 | H30: 45658 | I30: 45699
B31: In & Out Fees | C31: 40120 | D31: In & Out Fees | E31: Valero | F31: 1 | G31: 16425 | H31: 45748 | I31: 45779
B32: In & Out Fees | C32: 40120 | D32: In & Out Fees | E32: Trecora Recources | F32: 8009 | G32: 1265 | H32: 45748 | I32: 45779
B33: In & Out Fees | C33: 40120 | D33: In & Out Fees | E33: Trecora Recources | F33: 8010 | G33: 1760 | H33: 45802 | I33: 45809
B34: In & Out Fees | C34: 40120 | D34: In & Out Fees | E34: Trecora Recources | F34: 8011 | G34: 1155.5 | H34: 45833 | I34: 45840
B35: In & Out Fees | C35: 40120 | D35: In & Out Fees | E35: Valero | F35: 4 | G35: 1125 | H35: 45863 | I35: 45869
B36: In & Out Fees | C36: 40120 | D36: In & Out Fees | E36: Trecora Recources | F36: 8012 | G36: 660 | H36: 45863 | I36: 45869
B37: In & Out Fees | C37: 40120 | D37: In & Out Fees | E37: Valero | F37: 5 | G37: 15187.5 | H37: 45894 | I37: 45900
B38: In & Out Fees | C38: 40120 | D38: In & Out Fees | E38: Trecora Recources | F38: 8013 | G38: 880 | H38: 45894 | I38: 45900
B39: In & Out Fees | C39: 40120 | D39: In & Out Fees | E39: Valero | F39: 6 | G39: 13612.5 | H39: 45901 | I39: 45930
B40: In & Out Fees | C40: 40120 | D40: In & Out Fees | E40: Valero | F40: 8 | G40: 5737.5 | H40: 45986 | I40: 45991
B41: In & Out Fees | C41: 40120 | D41: In & Out Fees | E41: Trecora Resources | F41: 8015 | G41: 275 | H41: 45986 | I41: 45991
B42: In & Out Fees | C42: 40120 | D42: In & Out Fees | E42: Valero | F42: 9 | G42: 6750 | H42: 45992 | I42: 46022
B43: In & Out Fees | C43: 40120 | D43: In & Out Fees | E43: Trecora Resources | F43: 8016 | G43: 1210 | H43: 45992 | I43: 46022
D45: In & Out Fees Total | G45: =SUBTOTAL(9,G30:G44) -> 66483
...

Sheet Current Invoice Log (OP)
B2: Cost Category | C2: Cost Code # | D2: Bank Cost Category | E2: Cost Code Name | F2: Vendor | G2: Bill Number | H2: Amount Paid | I2: Requisition Month | J2: Invoice Date | L2: CURRENT REQ REPORT | M2: DUPLICATE(S)
B4: Travel | C4: 60210 | D4: Travel | E4: Travel | F4: Banyan Residential | G4: Dec_25 UBS CC Reimb. | H4: 217.32 | I4: 46016 | J4: 46022
E6: Travel Total | H6: =SUBTOTAL(9,H4:H5) -> 217.32
B8: Meals | C8: 60500 | D8: Meals | E8: Meals | F8: Banyan Residential | G8: Dec_25 UBS CC Reimb. | H8: 158.16 | I8: 46016 | J8: 46022
E10: Meals Total | H10: =SUBTOTAL(9,H8:H9) -> 158.16
B12: Site/Yard Maintenace | C12: 61050 | D12: Site/Yard Maintenace | E12: Site/Yard Maintenace | F12: Agri-Serv Industrial Maintenance | G12: 788995 | H12: 1061.6 | I12: 46016 | J12: 45993
E14: Site/Yard Maintenace Total | H14: =SUBTOTAL(9,H12:H13) -> 1061.6
B16: Track Repairs | C16: 61051 | D16: Track Repairs | E16: Track Repairs | F16: Mcallen Signal and Boring
E18: Track Repairs Total | H18: =SUBTOTAL(9,H16:H17) -> 0
B20: Crossing Repairs | C20: 61052 | D20: Crossing Repairs | E20: Crossing Repairs | F20: Mcallen Signal and Boring | G20: 12325CLR | H20: 700 | I20: 46016 | J20: 46001
E22: Crossing Repairs Total | H22: =SUBTOTAL(9,H20:H21) -> 700
B24: Landscape Maintenance | C24: 61056 | D24: Landscape Maintenance | E24: Landscape Maintenance | F24: Switch Yard Mowing | G24: 8021 | H24: 2500 | I24: 46016 | J24: 46022
E26: Landscape Maintenance Total | H26: =SUBTOTAL(9,H24:H25) -> 2500
B28: Utilities | C28: 61150 | D28: Utilities | E28: Utilities | F28: Banyan Residential | G28: Dec_25 UBS CC Reimb. | H28: 1184.69 | I28: 46016 | J28: 46022
E30: Utilities Total | H30: =SUBTOTAL(9,H28:H29) -> 1184.69
B32: Fuel | C32: 61164 | D32: Fuel | E32: Fuel | F32: Great Lakes Petroleum | G32: 2698593-IN | H32: 1952.87 | I32: 46016 | J32: 45994
B33: Fuel | C33: 61164 | D33: Fuel | E33: Fuel | F33: Great Lakes Petroleum | G33: 2716338-IN | H33: 2016.44 | I33: 46016 | J33: 46022
E35: Fuel Total | H35: =SUBTOTAL(9,H32:H34) -> 3969.31
B37: Accounting Fees | C37: 63000 | D37: Accounting Fees | E37: Accounting
E39: Accounting Fees Total | H39: =SUBTOTAL(9,H37:H38) -> 0
B41: Professional Fees | C41: 63025 | D41: Professional Fees | E41: Professional Fees | F41: Banyan Residential | G41: Dec_25 UBS CC Reimb. | H41: 1.25 | I41: 46016 | J41: 46022
E43: Professional Fees Total | H43: =SUBTOTAL(9,H41:H42) -> 1.25
B45: Management Fees - Hall Logistics | C45: 63026 | D45: Management Fees - Hall Logistics | E45: Management Fees - Hall Logistics | F45: Hall Rail Logistics
E47: Management Fees - Hall Logistics Total | H47: =SUBTOTAL(9,H45:H46) -> 0
B49: AM Fees - Banyan | C49: 63027 | D49: Management Fees - Banyan Residential | E49: Management Fees - Banyan Residential | F49: Banyan Residential LLC | G49: Dec_25 Management Fee | H49: 5683.19 | I49: 46016 | J49: 46022
E51: Management Fees - Banyan Residential Total | H51: =SUBTOTAL(9,H49:H50) -> 5683.19
B53: Asset Manager - (County Line) | C53: 63028 | D53: Asset Manager - (County Line) | E53: AM Staff Services - Asset Manager | F53: County Line Rail Operations | G53: Aug_25 Asset Manager Fees | I53: 45962 | J53: 45991
E55: AM Staff Services - Asset Manager Total | H55: =SUBTOTAL(9,H53:H54) -> 0
B57: Switchmen Salaries - Reimbursable | C57: 63032 | D57: Switchmen Healthcare – Reimbursable | E57: Switchmen Healthcare – Reimbursable | F57: Hall Rail Logistics
E59: Switchmen Healthcare - Reimbursable Total | H59: =SUBTOTAL(9,H57:H58) -> 0
B61: Mowing Assistance - Reimbursable | C61: 63033 | D61: Mowing Assistance - Reimbursable | E61: Mowing Assistance | F61: Switch Yard Mowing
E63: Mowing Assistance Total | H63: =SUBTOTAL(9,H61:H62) -> 0
B65: Switchmen Salaries - Reimbursable | C65: 63034 | D65: Switchmen Salaries - Reimbursable | E65: Switchmen Salaries - Reimbursable | F65: County Line Rail Operations | G65: 34 | H65: 11560.34 | I65: 46016 | J65: 46022
E67: Switchmen Salaries - Reimbursable Total | H67: =SUBTOTAL(9,H65:H66) -> 11560.34
B69: Offsite Manager | C69: 63041 | D69: Offsite Manager | E69: Management Fees | F69: County Line Rail Operations | G69: 38 | H69: -1603.53 | I69: 46016 | J69: 46022
E71: AM Staff Services - Accounting - Reimbursable Total | H71: =SUBTOTAL(9,H69:H70) -> -1603.53
B73: Offsite Staff | C73: 63042 | D73: Offsite Staff | E73: Offsite Staff | F73: County Line Rail Operations | G73: 34 | H73: 10116.6 | I73: 46016 | J73: 46022
E75: Management Fees Totals | H75: =SUBTOTAL(9,H73:H74) -> 10116.6
B77: Legal Fees | C77: 63050 | D77: Legal Fees | E77: Legal Fees - General | F77: Patrick M Knapp, PC | G77: 026
E79: Legal Fees - General Total | H79: =SUBTOTAL(9,H77:H78) -> 0
...

Sheet Prior Invoice Log (OP)
B2: Cost Category | C2: Cost Code # | D2: Bank Cost Category | E2: Cost Code Name | F2: Vendor | G2: Bill Number | H2: Amount Paid | I2: Requisition Month | J2: Invoice Date | L2: CURRENT REQ REPORT | M2: DUPLICATE(S)
B4: Travel | C4: 60210 | D4: Travel | E4: Travel | F4: Banyan Residential | G4: Jan_25 UBS CC Trx | H4: 154.1 | I4: 45682 | J4: 45688
B5: Travel | C5: 60210 | D5: Travel | E5: Travel | F5: Banyan Residential | G5: Dillon Schroeder Mileage (February) | H5: 50.25 | I5: 45689 | J5: 45716
B6: Travel | C6: 60210 | D6: Travel | E6: Travel | F6: Banyan Residential | G6: Feb_25 CC Exp | H6: 50.23 | I6: 45689 | J6: 45716
B7: Travel | C7: 60210 | D7: Travel | E7: Travel | F7: Banyan Residential | G7: Mar_25 CC Reimbursement | H7: 120.97 | I7: 45717 | J7: 45747
B8: Travel | C8: 60210 | D8: Travel | E8: Travel | F8: Dillon Schroeder | G8: Mar_25 Mileage Reimb. | H8: 75 | I8: 45717 | J8: 45747
B9: Travel | C9: 60210 | D9: Travel | E9: Travel | F9: Banyan Residential | G9: Jay Kennedy Mileage (Feb) | H9: 322 | I9: 45748 | J9: 45748
B10: Travel | C10: 60210 | D10: Travel | E10: Travel | F10: Banyan Residential | G10: Jay Kennedy Mileage (Mar) | H10: 161 | I10: 45748 | J10: 45748
B11: Travel | C11: 60210 | D11: Travel | E11: Travel | F11: Banyan Residential | G11: Apr_25 UBS CC Reimbursement | H11: 1048.73 | I11: 45748 | J11: 45770
B12: Travel | C12: 60210 | D12: Travel | E12: Travel | F12: Banyan Residential | G12: Dillon Schroeder Mileage (May) | H12: 154 | I12: 45802 | J12: 45808
B13: Travel | C13: 60210 | D13: Travel | E13: Travel | F13: Banyan Residential | G13: Dillon Schroeder Mileage (June) | H13: 319.2 | I13: 45833 | J13: 45838
B14: Travel | C14: 60210 | D14: Travel | E14: Travel | F14: Banyan Residential | G14: Jay Kennedy Mileage (Juen) | H14: 161 | I14: 45833 | J14: 45838
B15: Travel | C15: 60210 | D15: Travel | E15: Travel | F15: Banyan Residential | G15: June 2025 UBS Credit Card Reimb | H15: 959.28 | I15: 45833 | J15: 45838
... B26: Travel | C26: 60210 | D26: Travel | E26: Travel | F26: Banyan Residential | G26: Dec_25 UBS CC Reimb. | H26: 217.32 | I26: 46016 | J26: 46022
E28: Travel Total | H28: =SUBTOTAL(9,H4:H27) -> 7744.65
B30: Meals | C30: 60500 | D30: Meals | E30: Meals | F30: Banyan Residential | G30: Jul_25 UBS CC Reimb. | H30: 59.22 | I30: 45839 | J30: 45869
B31: Meals | C31: 60500 | D31: Meals | E31: Meals | F31: Banyan Residential | G31: Sep_25 UBS CC | H31: 95.48 | I31: 45925 | J31: 45922
B32: Meals | C32: 60500 | D32: Meals | E32: Meals | F32: Banyan Residential | G32: Oct_25 UBS CC | H32: 62.45 | I32: 45931 | J32: 45961
B33: Meals | C33: 60500 | D33: Meals | E33: Meals | F33: Banyan Residential | G33: Nov_25 UBS CC Reimb. | H33: 171.23 | I33: 45962 | J33: 45991
B34: Meals | C34: 60500 | D34: Meals | E34: Meals | F34: Banyan Residential | G34: Dec_25 UBS CC Reimb. | H34: 158.16 | I34: 46016 | J34: 46022
E36: Meals Total | H36: =SUBTOTAL(9,H30:H35) -> 546.54
B38: Site/Yard Maintenace | C38: 61050 | D38: Site/Yard Maintenace | E38: Site/Yard Maintenace | F38: Biskamp Electric, Inc | G38: 550086-1 | H38: 4239.07 | I38: 45839 | J38: 45849
B39: Site/Yard Maintenace | C39: 61050 | D39: Site/Yard Maintenace | E39: Site/Yard Maintenace | F39: Banyan Residential | G39: Oct_25 UBS CC | H39: 1798 | I39: 45931 | J39: 45961
B40: Site/Yard Maintenace | C40: 61050 | D40: Site/Yard Maintenace | E40: Site/Yard Maintenace | F40: Kauffman Co. | G40: I2510-34 | H40: 346 | I40: 45962 | J40: 45981
B41: Site/Yard Maintenace | C41: 61050 | D41: Site/Yard Maintenace | E41: Site/Yard Maintenace | F41: Agri-Serv Industrial Maintenance | G41: 788995 | H41: 1061.6 | I41: 46016 | J41: 45993
E43: Site/Yard Maintenance Total | H43: =SUBTOTAL(9,H38:H42) -> 7444.67
B45: Track Repairs | C45: 61051 | D45: Track Repairs | E45: Track Repairs | F45: Mcallen Signal and Boring | G45: 11025 | H45: 1775 | I45: 45682 | J45: 45671
E47: Track Repairs Total | H47: =SUBTOTAL(9,H45:H46) -> 1775
B49: Crossing Repairs | C49: 61052 | D49: Crossing Repairs | E49: Crossing Repairs | F49: Mcallen Signal and Boring | G49: 1525CLR | H49: 700 | I49: 45682 | J49: 45670
B50: Crossing Repairs | C50: 61052 | D50: Crossing Repairs | E50: Crossing Repairs | F50: Mcallen Signal and Boring | G50: 12925CLR | H50: 764 | I50: 45689 | J50: 45692
B51: Crossing Repairs | C51: 61052 | D51: Crossing Repairs | E51: Crossing Repairs | F51: Mcallen Signal and Boring | G51: 22825CLR | H51: 700 | I51: 45717 | J51: 45721
B52: Crossing Repairs | C52: 61052 | D52: Crossing Repairs | E52: Crossing Repairs | F52: Mcallen Signal and Boring | G52: 33125CLR | H52: 700 | I52: 45748 | J52: 45756
B53: Crossing Repairs | C53: 61052 | D53: Crossing Repairs | E53: Crossing Repairs | F53: Mcallen Signal and Boring | G53: 42625CLR | H53: 700 | I53: 45802 | J53: 45778
B54: Crossing Repairs | C54: 61052 | D54: Crossing Repairs | E54: Crossing Repairs | F54: Mcallen Signal and Boring | G54: 52225CLR | H54: 700 | I54: 45802 | J54: 45805
B55: Crossing Repairs | C55: 61052 | D55: Crossing Repairs | E55: Crossing Repairs | F55: Mcallen Signal and Boring | G55: 61925CLR | H55: 700 | I55: 45833 | J55: 45833
B56: Crossing Repairs | C56: 61052 | D56: Crossing Repairs | E56: Crossing Repairs | F56: Mcallen Signal and Boring | G56: 71725CLR | H56: 700 | I56: 45839 | J56: 45861
B57: Crossing Repairs | C57: 61052 | D57: Crossing Repairs | E57: Crossing Repairs | F57: Mcallen Signal and Boring | G57: 81425CLR | H57: 700 | I57: 45870 | J57: 45896
B58: Crossing Repairs | C58: 61052 | D58: Crossing Repairs | E58: Crossing Repairs | F58: Mcallen Signal and Boring | G58: 91125CLR | H58: 700 | I58: 45925 | J58: 45916
B59: Crossing Repairs | C59: 61052 | D59: Crossing Repairs | E59: Crossing Repairs | F59: Mcallen Signal and Boring | G59: 101425CLR | H59: 700 | I59: 45931 | J59: 45947
B60: Crossing Repairs | C60: 61052 | D60: Crossing Repairs | E60: Crossing Repairs | F60: Mcallen Signal and Boring | G60: 11425CLR | H60: 700 | I60: 45962 | J60: 45965
...

Sheet Bridge Approvd Budget to Actual
B1: PROJECT FUNDING REQUISITION
B2: Bishop Arts JV, LLC
B3: Application Period: 12/31/21
B4: Requisition: #14
D6: Bishop Arts | E6: Previous Contingency | F6: Current Contingency | G6: Bishop Arts | H6: Previous Application | I6: Payment this period | J6: Total Complete & Draw To Date | L6: Balance remaining
A7: Yardi Code | B7: COA# | C7: Account Name | D7: Approved JV Budget | E7: Funding & Reallocation | F7: Funding & Reallocation | G7: Current Approved Budget | H7: Inception to 11/30/21 | I7: 12/31/21 | J7: Incurred to 12/31/21 | K7: Percent Drawn | L7: As of 12/31/21
