Workbook

Sheet Sub Close Summary
A1: Summary close details for Legacy Knight
A3: Partner Name | B3: Total Contribution - Investments | C3: Total Contributions - Management Fees | D3: Total Interest - Contributions (Investment) | E3: Total Interest - Contributions (Management Fees) | F3: Total Call
A4: Legacy Knight Strategic Opportunities Fund LLC - CL Rail Series | B4: ='Subsequent Close'!T82-'Subsequent Close'!M82+'Subsequent Close'!W82-'Subsequent Close'!P82+'Subsequent Close'!X82-'Subsequent Close'!Q82 -> -4523875.5 | C4: ='Subsequent Close - OLD B4 25k'!U82 -> -147745.92 | D4: =-'Closing Interest'!O25 -> -327055.93 | E4: =-'Management Fees - New Investor'!M20 -> -9508.8323 | F4: =SUM(B4:E4) -> -5008186.2
A5: James Bloomingdale | B5: ='Subsequent Close'!T85+'Subsequent Close'!W85+'Subsequent Close'!X85 -> -17826.525 | C5: ='Subsequent Close'!U85 -> -551.29076 | D5: =-'Closing Interest'!O26 -> -1288.7779 | E5: =-'Management Fees - New Investor'!M34 -> -35.480718 | F5: =SUM(B5:E5) -> -19702.075
A6: Total Call | B6: =SUM(B4:B5) -> -4541702 | C6: =SUM(C4:C5) -> -148297.21 | D6: =SUM(D4:D5) -> -328344.71 | E6: =SUM(E4:E5) -> -9544.3131 | F6: =SUM(F4:F5) -> -5027888.3
A8: Checking
A9: Difference from supporting workpapers (closing interest and management fee tabs) | B9: =B6+'Closing Interest'!O18 -> -0.01051553 | C9: =C6-'Subsequent Close'!U86 | D9: =D6+'Closing Interest'!O29 | E9: =E6+'Management Fees - New Investor'!M20+'Management Fees - New Investor'!M34 -> -1.9895197e-13
A11: Legacy Knight
A12: Total contributed at rebalance date: | B12: ='Subsequent Close'!R86 -> -1.4226399e+08
A13: Total management fee contributions - other investors | B13: =-'Subsequent Close'!N86 -> 2653283.9
A14: Total Investment Contributions for rebalance | B14: =SUM(B12:B13) -> -1.3961071e+08
B15: ='Subsequent Close'!I82-'Subsequent Close'!H82 -> 0.032403499
A16: Total Investment Contribution by Legacy Knight: | B16: =B15*B14 -> -4523875.5
A18: James Bloomingdale
A19: Total contributed at rebalance date: | B19: =B12 -> -1.4226399e+08
A20: Total management fee contributions - other investors | B20: =B13 -> 2653283.9
A21: Total Investment Contributions for rebalance | B21: =SUM(B19:B20) -> -1.3961071e+08
B22: ='Subsequent Close'!I85 -> 0.00012768738
A23: Total Investment Contribution by James Bloomingdale | B23: =B22*B21 -> -17826.525
A26: JE# LC05282601 | B26: Date | C26: 46147
A27: Account# | B27: Debit | C27: Credit | D27: Memo | E27: Investor
A28: 301200 Contributions:Contribution - Investment | C28: =ROUND(-'Subsequent Close'!T82+'Subsequent Close'!M82,2) -> 4069952.5 | D28: To record contribution - investment for Legacy Knight dtd 5/5/26 | E28: Legacy Knight Strategic Opportunities Fund LLC - CL Rail Series
A29: 301300 Contributions:Contribution - Mgmt Fees | C29: =ROUND(+'Subsequent Close'!N82-'Subsequent Close'!U82-'Subsequent Close'!V82,2) -> 147745.92 | D29: To record contribution - management fee for Legacy Knight dtd 5/5/26 | E29: Legacy Knight Strategic Opportunities Fund LLC - CL Rail Series
A30: 301800 Contributions:Contribution - Org Exp | C30: =ROUND(+'Subsequent Close'!P82-'Subsequent Close'!W82,2) -> 1811.82 | D30: To record contribution - org exp for Legacy Knight dtd 5/5/26 | E30: Legacy Knight Strategic Opportunities Fund LLC - CL Rail Series
A31: 301100 Contributions:Contribution - General | C31: =ROUND(+'Subsequent Close'!Q82-'Subsequent Close'!X82,2) -> 452111.18 | D31: To record contribution - General for Legacy Knight dtd 5/5/26 | E31: Legacy Knight Strategic Opportunities Fund LLC - CL Rail Series
A32: 210700 Payable - Other | C32: =ROUND(+'Subsequent Close'!AS82,2) -> 327055.93 | D32: To record payments re interest payable for Equalization distribution for Legacy Knight dtd 5/5/26 | E32: Legacy Knight Strategic Opportunities Fund LLC - CL Rail Series
A33: 210700 Payable - Other | C33: =ROUND(+'Subsequent Close'!BA82,2) -> 9508.83 | D33: To record payments re interest payable for management fee due to subsequent closing for Legacy Knight dtd 5/5/26 | E33: Legacy Knight Strategic Opportunities Fund LLC - CL Rail Series
A34: 12000 Accounts Receivable | B34: =SUM(C28:C33) -> 5008186.2 | D34: To record cash received from Legacy Knight dtd 5/5/26 | E34: Legacy Knight Strategic Opportunities Fund LLC - CL Rail Series
A38: JE# LC05282602 | B38: Date | C38: 46147
A39: Account# | B39: Debit | C39: Credit | D39: Memo | E39: Investor
A40: 301200 Contributions:Contribution - Investment | C40: =ROUND(-'Subsequent Close'!T85,2) -> 16037.82 | D40: To record contribution - investment for James Bloomingdale dtd 5/5/26 | E40: James Bloomingdale
A41: 301300 Contributions:Contribution - Mgmt Fees | C41: =ROUND(-'Subsequent Close'!U85,2) -> 551.29 | D41: To record contribution - management fee for James Bloomingdale dtd 5/5/26 | E41: James Bloomingdale
A42: 301800 Contributions:Contribution - Org Exp | C42: =ROUND(-'Subsequent Close'!W85,2) -> 7.14 | D42: To record contribution - org exp for James Bloomingdale dtd 5/5/26 | E42: James Bloomingdale
A43: 301100 Contributions:Contribution - General | C43: =ROUND(-'Subsequent Close'!X85,2) -> 1781.56 | D43: To record contribution - General for James Bloomingdale dtd 5/5/26 | E43: James Bloomingdale
A44: 210700 Payable - Other | C44: =ROUND(+'Subsequent Close'!AS85,2) -> 1288.78 | D44: To record payments re interest payable for Equalization distribution for James Bloomingdale dtd 5/5/26 | E44: James Bloomingdale
A45: 210700 Payable - Other | C45: =ROUND(+'Subsequent Close'!BA85,2) -> 35.48 | D45: To record payments re interest payable for management fee due to subsequent closing for James Bloomingdale dtd 5/5/26 | E45: James Bloomingdale
A46: 12000 Accounts Receivable | B46: =SUM(C40:C45) -> 19702.07 | D46: To record cash recivable from James Bloomingdale dtd 5/5/26 | E46: James Bloomingdale
A48: JE# LC05282603 | B48: Date | C48: 46161 | G48: Summary of JE | H48: =SUM(H50:H68) -> 10974728 | I48: =SUM(I50:I68) -> 10974728 | J48: =+H48-I48 -> 0
A49: Account# | B49: Debit | C49: Credit | D49: Memo | E49: Investor | G49: Acct# | H49: Debit | I49: Credit
A50: 100200 Cash Checking | C50: =-ROUND(_xlfn.XLOOKUP(E50,'May 26 Distribution Checking'!A:A,'May 26 Distribution Checking'!AA:AA),2) -> 8777.9 | D50: To record total of equalization distribution per Legacy Knight Subsequent Closing in Q2'26. | E50: 1999 Britta Biesecker Declaration of Trust DTD 5/12/99 | G50: 100200 Cash Checking | I50: =SUMIFS(C:C,A:A,G50,D:D,J50) -> 3152712.3 | J50: To record total of equalization distribution per Legacy Knight Subsequent Closing in Q2'26.
...

Sheet Sub Close Calcu
A1: Totals | B1: 1.8906569e+08 | C1: 698301.63 | D1: 8.3673513e-11 | E1: 148297.21 | H1: 1.4441229e+08 | K1: -1.4241229e+08
C2: Tied to GCM close WB | D2: Based on recalculated GCM close | E2: Tied to LK Close WB | N2: DISTRIBUTION - Subsequent Close | Q2: Not part of distribution on capital | S2: Not part of distribution on capital | X2: MAY 2026 - Capital Call
A3: Investor Name | B3: Total Commitment / Contributed Capital @ GCM Close | C3: Distribution - GCM Equalization | D3: Correcting Distribution (Odyssey commitment overstatement) | E3: Distribution - Legacy Knight Equalization | F3: Distribution - James & Natalie Bloomingdale Equalization | G3: May 2026 - Capital Call | H3: Ending Capital (Recalculated) | I3: Unfunded per books | K3: Ending Capital Per Sub Close WB | L3: Diff | N3: Call From Subsequent Close Investor | O3: Total GCM True-Up to Investor | P3: Total Investment Distribution to Investors | Q3: Total Interest Distribution to Investors | R3: Total Distribution to Investor | S3: Management Fee Interest Distribution | T3: Call received as of 5.18.26 | U3: Net to Investor | V3: Return of Capital Call re Sub Close | X3: Call - Investments | Y3: Call - Management Fees | Z3: Total Capital Call | AB3: Net cash from/(to) investor
A4: 1999 Britta Biesecker Declaration of Trust DTD 5/12/99 | B4: 500000 | C4: -123101.89 | D4: -335.39146 | E4: -12681.664 | G4: 5107.4951 | H4: 368988.55 | I4: 131011.45 | K4: -363881.05 | L4: 0.0039233036 | O4: -335.39146 | P4: -12681.664 | Q4: -868.33498 | R4: -13885.391 | U4: -13885.391 | V4: =+P4 -> -12681.664 | X4: 5107.4951 | Y4: 0 | Z4: 5107.4951 | AB4: -8777.8957
A5: 1999 Frederick N Biesecker II Declaration of Trust DTD 5/12/99 | B5: 700000 | C5: -172342.65 | D5: -469.54804 | E5: -17754.33 | G5: 7150.4931 | H5: 516583.96 | I5: 183416.04 | K5: -509433.47 | L5: -0.0025073755 | O5: -469.54804 | P5: -17754.33 | Q5: -1215.669 | R5: -19439.547 | U5: -19439.547 | V5: =+P5 -> -17754.33 | X5: 7150.4931 | Y5: 0 | Z5: 7150.4931 | AB5: -12289.054
A6: 1999 Lissa Biesecker Longacre Declaration of Trust DTD 5/12/99 | B6: 600000 | C6: -147722.27 | D6: -402.46975 | E6: -15217.997 | G6: 6128.9941 | H6: 442786.25 | I6: 157213.75 | K6: -436657.26 | L6: 0.00070796418 | O6: -402.46975 | P6: -15217.997 | Q6: -1042.002 | R6: -16662.469 | U6: -16662.469 | V6: =+P6 -> -15217.997 | X6: 6128.9941 | Y6: 0 | Z6: 6128.9941 | AB6: -10533.475
A7: Abigail Levy | B7: 750000 | C7: -184652.84 | D7: -503.08718 | E7: -19022.497 | G7: 7661.2426 | H7: 553482.82 | I7: 196517.18 | K7: -545821.58 | L7: -0.0091150449 | O7: -503.08718 | P7: -19022.497 | Q7: -1302.5025 | R7: -20828.086 | U7: -20828.086 | V7: =+P7 -> -19022.497 | X7: 7661.2426 | Y7: 0 | Z7: 7661.2426 | AB7: -13166.844
A8: AKWT LLC | B8: 78300.32 | C8: -19495.079 | D8: -52.522517 | E8: -1985.9568 | G8: 799.837 | H8: 57566.599 | I8: 20733.721 | K8: -56766.766 | L8: -0.003617733 | O8: -52.522517 | P8: -1985.9568 | Q8: -135.98181 | R8: -2174.4611 | U8: -2174.4611 | V8: =+P8 -> -1985.9568 | X8: 799.837 | Y8: 0 | Z8: 799.837 | AB8: -1374.6241
A9: Alexander S. Bloomingdale | B9: 144197.96 | C9: -36027.743 | D9: -96.725527 | E9: -3657.3403 | G9: 1472.9807 | H9: 105889.13 | I9: 38308.828 | K9: -104416.15 | L9: 0.00071551031 | O9: -96.725527 | P9: -3657.3403 | Q9: -250.42427 | R9: -4004.4901 | U9: -4004.4901 | V9: =+P9 -> -3657.3403 | X9: 1472.9807 | Y9: 0 | Z9: 1472.9807 | AB9: -2531.5093
A10: Alexander Sharpe Moore | B10: 156600.63 | C10: -38990.166 | D10: -105.04503 | E10: -3971.9133 | G10: 1599.6739 | H10: 115133.18 | I10: 41467.45 | K10: -113533.5 | L10: 0.0016104754 | O10: -105.04503 | P10: -3971.9133 | Q10: -271.96361 | R10: -4348.9219 | U10: -4348.9219 | V10: =+P10 -> -3971.9133 | X10: 1599.6739 | Y10: 0 | Z10: 1599.6739 | AB10: -2749.248
A11: All Dogs Go To Heaven, LLC | B11: 523296.86 | C11: -130540.75 | D11: -351.01859 | E11: -13272.55 | G11: 5345.4723 | H11: 384478.01 | I11: 138818.85 | K11: -379132.54 | L11: -0.0017302958 | O11: -351.01859 | P11: -13272.55 | Q11: -908.79394 | R11: -14532.363 | U11: -14532.363 | V11: =+P11 -> -13272.55 | X11: 5345.4723 | Y11: 0 | Z11: 5345.4723 | AB11: -9186.8906
A12: Alten Investments LLC | B12: 1000000 | C12: -246203.78 | D12: -670.78291 | E12: -25363.329 | G12: 10214.99 | H12: 737977.09 | I12: 262022.91 | K12: -727762.11 | L12: -0.0021533932 | O12: -670.78291 | P12: -25363.329 | Q12: -1736.67 | R12: -27770.782 | U12: -27770.782 | V12: =+P12 -> -25363.329 | X12: 10214.99 | Y12: 0 | Z12: 10214.99 | AB12: -17555.791
A13: Avery Ryan Klann | B13: 391501.58 | C13: -97475.42 | D13: -262.61257 | E13: -9929.7833 | G13: 3999.1848 | H13: 287832.95 | I13: 103668.63 | K13: -283833.76 | L13: -0.00039678211 | O13: -262.61257 | P13: -9929.7833 | Q13: -679.90904 | R13: -10872.305 | U13: -10872.305 | V13: =+P13 -> -9929.7833 | X13: 3999.1848 | Y13: 0 | Z13: 3999.1848 | AB13: -6873.1201
A14: BBR Real Assets Fund 2024 LLC | B14: 10000000 | C14: -2462037.9 | D14: -6707.8291 | E14: -253633.29 | G14: 102149.9 | H14: 7379770.9 | I14: 2620229.1 | K14: -7277621 | L14: -0.0015339297 | O14: -6707.8291 | P14: -253633.29 | Q14: -17366.7 | R14: -277707.82 | U14: -277707.82 | V14: =+P14 -> -253633.29 | X14: 102149.9 | Y14: 0 | Z14: 102149.9 | AB14: -175557.91
A15: Belclaire Asset Management, LLC | B15: 914798.44 | C15: -228016.16 | D15: -613.63116 | E15: -23202.334 | G15: 9344.657 | H15: 672310.97 | I15: 242487.47 | K15: -662966.32 | L15: -0.0021270778 | O15: -613.63116 | P15: -23202.334 | Q15: -1588.703 | R15: -25404.668 | U15: -25404.668 | V15: =+P15 -> -23202.334 | X15: 9344.657 | Y15: 0 | Z15: 9344.657 | AB15: -16060.011
... A56: Nahas Investments II LLC | B56: 391501.58 | C56: -97475.42 | D56: -262.61257 | E56: -9929.7833 | G56: 3999.1848 | H56: 287832.95 | I56: 103668.63 | K56: -283833.76 | L56: -0.00039678211 | O56: -262.61257 | P56: -9929.7833 | Q56: -679.90904 | R56: -10872.305 | U56: -10872.305 | V56: =+P56 -> -9929.7833 | X56: 3999.1848 | Y56: 0 | Z56: 3999.1848 | AB56: -6873.1201
A57: Odyssey Holdings, LLC | B57: 703163.88 | C57: -310280.58 | D57: 126350.37 | E57: -17834.577 | G57: 7182.8121 | H57: 508581.9 | I57: 194581.98 | K57: -501398.75 | L57: 0.34158148 | O57: 126350.37 | P57: -17834.577 | Q57: -1221.1636 | R57: 107294.63 | S57: -9544.3131 | T57: -126350 | U57: -28599.687 | V57: =+P57+T57 -> -144184.58 | X57: 7182.8121 | Y57: 0 | Z57: 7182.8121 | AB57: -21416.875
A58: Pease River Holdings LLC | B58: 78300.32 | C58: -19495.079 | D58: -52.522517 | E58: -1985.9568 | G58: 799.837 | H58: 57566.599 | I58: 20733.721 | K58: -56766.766 | L58: -0.003617733 | O58: -52.522517 | P58: -1985.9568 | Q58: -135.98181 | R58: -2174.4611 | U58: -2174.4611 | V58: =+P58 -> -1985.9568 | X58: 799.837 | Y58: 0 | Z58: 799.837 | AB58: -1374.6241
A59: PT Burros, LLC | B59: 329488.2 | C59: -82663.322 | D59: -221.01505 | E59: -8356.9175 | G59: 3365.7187 | H59: 241612.66 | I59: 87875.536 | K59: -238246.94 | L59: 0.0016662164 | O59: -221.01505 | P59: -8356.9175 | Q59: -572.21226 | R59: -9150.1448 | U59: -9150.1448 | V59: =+P59 -> -8356.9175 | X59: 3365.7187 | Y59: 0 | Z59: 3365.7187 | AB59: -5784.4261
A60: Robert D. Falese III | B60: 877590.41 | C60: -219128.91 | D60: -588.67265 | E60: -22258.614 | G60: 8964.5774 | H60: 644578.79 | I60: 233011.62 | K60: -635614.21 | L60: 0.0028799096 | O60: -588.67265 | P60: -22258.614 | Q60: -1524.0849 | R60: -24371.372 | U60: -24371.372 | V60: =+P60 -> -22258.614 | X60: 8964.5774 | Y60: 0 | Z60: 8964.5774 | AB60: -15406.794
A61: Robert Parker Yates | B61: 39150.16 | C61: -9747.5493 | D61: -26.261258 | E61: -992.97838 | G61: 399.9185 | H61: 28783.29 | I61: 10366.87 | K61: -28383.373 | L61: -0.0018088665 | O61: -26.261258 | P61: -992.97838 | Q61: -67.990907 | R61: -1087.2305 | U61: -1087.2305 | V61: =+P61 -> -992.97838 | X61: 399.9185 | Y61: 0 | Z61: 399.9185 | AB61: -687.31205
A62: Robert S. Shafir & Donna R. Shafir TEN/COM | B62: 1500000 | C62: -369305.68 | D62: -1006.1744 | E62: -38044.993 | G62: 15322.485 | H62: 1106965.6 | I62: 393034.36 | K62: -1091643.2 | L62: 0.00176991 | O62: -1006.1744 | P62: -38044.993 | Q62: -2605.005 | R62: -41656.172 | U62: -41656.172 | V62: =+P62 -> -38044.993 | X62: 15322.485 | Y62: 0 | Z62: 15322.485 | AB62: -26333.687
A63: Robert S. Shafir 2011 Children's Trust | B63: 1000000 | C63: -246203.78 | D63: -670.78291 | E63: -25363.329 | G63: 10214.99 | H63: 737977.09 | I63: 262022.91 | K63: -727762.11 | L63: -0.0021533932 | O63: -670.78291 | P63: -25363.329 | Q63: -1736.67 | R63: -27770.782 | U63: -27770.782 | V63: =+P63 -> -25363.329 | X63: 10214.99 | Y63: 0 | Z63: 10214.99 | AB63: -17555.791
A64: Romar Partners, LP | B64: 1000000 | C64: -246203.78 | D64: -670.78291 | E64: -25363.329 | G64: 10214.99 | H64: 737977.09 | I64: 262022.91 | K64: -727762.11 | L64: -0.0021533932 | O64: -670.78291 | P64: -25363.329 | Q64: -1736.67 | R64: -27770.782 | U64: -27770.782 | V64: =+P64 -> -25363.329 | X64: 10214.99 | Y64: 0 | Z64: 10214.99 | AB64: -17555.791
A65: Steven and Chani Laufer 2012 Dynasty Trust | B65: 2000000 | C65: -492407.57 | D65: -1341.5658 | E65: -50726.657 | G65: 20429.98 | H65: 1475954.2 | I65: 524045.81 | K65: -1455524.2 | L65: 0.0056932139 | O65: -1341.5658 | P65: -50726.657 | Q65: -3473.3399 | R65: -55541.563 | U65: -55541.563 | V65: =+P65 -> -50726.657 | X65: 20429.98 | Y65: 0 | Z65: 20429.98 | AB65: -35111.583
A66: Steven M. Laufer 2012 Trust | B66: 1000000 | C66: -246203.78 | D66: -670.78291 | E66: -25363.329 | G66: 10214.99 | H66: 737977.09 | I66: 262022.91 | K66: -727762.11 | L66: -0.0021533932 | O66: -670.78291 | P66: -25363.329 | Q66: -1736.67 | R66: -27770.782 | U66: -27770.782 | V66: =+P66 -> -25363.329 | X66: 10214.99 | Y66: 0 | Z66: 10214.99 | AB66: -17555.791
A67: Stewart Tate | B67: 523296.86 | C67: -130540.75 | D67: -351.01859 | E67: -13272.55 | G67: 5345.4723 | H67: 384478.01 | I67: 138818.85 | K67: -379132.54 | L67: -0.0017302958 | O67: -351.01859 | P67: -13272.55 | Q67: -908.79394 | R67: -14532.363 | U67: -14532.363 | V67: =+P67 -> -13272.55 | X67: 5345.4723 | Y67: 0 | Z67: 5345.4723 | AB67: -9186.8906
A68: TC Wilson Family Trust | B68: 156600.63 | C68: -38990.166 | D68: -105.04503 | E68: -3971.9133 | G68: 1599.6739 | H68: 115133.18 | I68: 41467.45 | K68: -113533.5 | L68: 0.0016104754 | O68: -105.04503 | P68: -3971.9133 | Q68: -271.96361 | R68: -4348.9219 | U68: -4348.9219 | V68: =+P68 -> -3971.9133 | X68: 1599.6739 | Y68: 0 | Z68: 1599.6739 | AB68: -2749.248
A69: Terminal Refrigerating & Warehousing Corp. | B69: 0 | E69: 0 | G69: 0 | H69: 0 | I69: 0 | K69: 0 | L69: 0 | O69: 0 | P69: 0 | Q69: 0 | R69: 0 | U69: 0 | V69: =+P69 -> 0 | X69: 0 | Y69: 0 | Z69: 0 | AB69: 0
A70: The 2015 Pipe Reality Delaware Trust | B70: 1000000 | C70: -246203.78 | D70: -670.78291 | E70: -25363.329 | G70: 10214.99 | H70: 737977.09 | I70: 262022.91 | K70: -727762.11 | L70: -0.0021533932 | O70: -670.78291 | P70: -25363.329 | Q70: -1736.67 | R70: -27770.782 | U70: -27770.782 | V70: =+P70 -> -25363.329 | X70: 10214.99 | Y70: 0 | Z70: 10214.99 | AB70: -17555.791
A71: The David L. Schnadig 2017 Trust | B71: 1000000 | C71: -246203.78 | D71: -670.78291 | E71: -25363.329 | G71: 10214.99 | H71: 737977.09 | I71: 262022.91 | K71: -727762.11 | L71: -0.0021533932 | O71: -670.78291 | P71: -25363.329 | Q71: -1736.67 | R71: -27770.782 | U71: -27770.782 | V71: =+P71 -> -25363.329 | X71: 10214.99 | Y71: 0 | Z71: 10214.99 | AB71: -17555.791
A72: The Diane Rosen 2021 Irrevocable Family Trust | B72: 600000 | C72: -147722.27 | D72: -402.46975 | E72: -15217.997 | G72: 6128.9941 | H72: 442786.25 | I72: 157213.75 | K72: -436657.26 | L72: 0.00070796418 | O72: -402.46975 | P72: -15217.997 | Q72: -1042.002 | R72: -16662.469 | U72: -16662.469 | V72: =+P72 -> -15217.997 | X72: 6128.9941 | Y72: 0 | Z72: 6128.9941 | AB72: -10533.475
A73: The Mark T. Kirchdorfer 2015 Family Delaware Dynasty Trust | B73: 1000000 | C73: -246203.78 | D73: -670.78291 | E73: -25363.329 | G73: 10214.99 | H73: 737977.09 | I73: 262022.91 | K73: -727762.11 | L73: -0.0021533932 | O73: -670.78291 | P73: -25363.329 | Q73: -1736.67 | R73: -27770.782 | U73: -27770.782 | V73: =+P73 -> -25363.329 | X73: 10214.99 | Y73: 0 | Z73: 10214.99 | AB73: -17555.791
A74: University of Southern California | B74: 20000000 | C74: -4849075.7 | D74: -13415.658 | E74: -507266.57 | G74: 204299.8 | H74: 14834542 | I74: 5165458.1 | K74: -14630242 | L74: -0.0030678612 | O74: -13415.658 | P74: -507266.57 | Q74: -34733.399 | R74: -555415.63 | U74: -555415.63 | V74: =+P74 -> -507266.57 | X74: 204299.8 | Y74: 0 | Z74: 204299.8 | AB74: -351115.83
A75: Walker D. Zimmerman | B75: 250000 | C75: -59713.311 | D75: -167.69573 | E75: -6340.8322 | G75: 2553.7475 | H75: 186331.91 | I75: 63668.091 | K75: -183778.16 | L75: -0.0030383483 | O75: -167.69573 | P75: -6340.8322 | Q75: -434.16749 | R75: -6942.6954 | U75: -6942.6954 | V75: =+P75 -> -6340.8322 | X75: 2553.7475 | Y75: 0 | Z75: 2553.7475 | AB75: -4388.9479
A76: Wilson Family Trust DTD 3-6-1987 | B76: 313201.26 | C76: -77980.351 | D76: -210.09005 | E76: -7943.8265 | G76: 3199.3478 | H76: 230266.34 | I76: 82934.92 | K76: -227067 | L76: -0.0067790492 | O76: -210.09005 | P76: -7943.8265 | Q76: -543.92722 | R76: -8697.8438 | U76: -8697.8438 | V76: =+P76 -> -7943.8265 | X76: 3199.3478 | Y76: 0 | Z76: 3199.3478 | AB76: -5498.496
A77: Wilson GST Exempt Trust | B77: 313201.26 | C77: -77980.351 | D77: -210.09005 | E77: -7943.8265 | G77: 3199.3478 | H77: 230266.34 | I77: 82934.92 | K77: -227067 | L77: -0.0067790492 | O77: -210.09005 | P77: -7943.8265 | Q77: -543.92722 | R77: -8697.8438 | U77: -8697.8438 | V77: =+P77 -> -7943.8265 | X77: 3199.3478 | Y77: 0 | Z77: 3199.3478 | AB77: -5498.496
A78: Texas Emerging Managers Private Markets Program, L.P. (2025-1 RE Investment Series) | B78: 5000000 | C78: 3768981.1 | D78: -3353.9146 | E78: -126816.64 | G78: 51074.951 | H78: 3689885.5 | I78: 1310114.5 | K78: -3638810.5 | L78: 3.0486262e-09 | O78: -3353.9146 | P78: -126816.64 | Q78: -8683.3498 | R78: -138853.91 | U78: -138853.91 | V78: =+P78 -> -126816.64 | X78: 51074.951 | Y78: 0 | Z78: 51074.951 | AB78: -87778.957
A79: GCM Grosvenor NJ RE Emerging Managers Program, LP (2023-1 Investment Series) | B79: 7500000 | C79: 5653471.6 | D79: -5030.8718 | E79: -190224.97 | G79: 76612.426 | H79: 5534828.2 | I79: 1965171.8 | K79: -5458215.8 | L79: 1.4551915e-10 | O79: -5030.8718 | P79: -190224.97 | Q79: -13025.025 | R79: -208280.86 | U79: -208280.86 | V79: =+P79 -> -190224.97 | X79: 76612.426 | Y79: 0 | Z79: 76612.426 | AB79: -131668.44
A80: GCM Grosvenor - NYSTRS Real Estate Investment Partners, L.P. (2024-1 Series) | B80: 5000000 | C80: 3768981.1 | D80: -3353.9146 | E80: -126816.64 | G80: 51074.951 | H80: 3689885.5 | I80: 1310114.5 | K80: -3638810.5 | L80: 3.0486262e-09 | O80: -3353.9146 | P80: -126816.64 | Q80: -8683.3498 | R80: -138853.91 | U80: -138853.91 | V80: =+P80 -> -126816.64 | X80: 51074.951 | Y80: 0 | Z80: 51074.951 | AB80: -87778.957
...

Sheet Subsequent Close
A1: County Line Rail Subsequent Close Workbook - Legacy Knight | M1: Amount before Rebalance | T1: Rebalance
M2: Contribution - Investment | P2: Contribution - Org Exp | Q2: Contribution - General | T2: Contribution - Investment (Rebalanced) | W2: Contribution - Org Exp (Rebalanced) | X2: Contribution - General (Rebalanced)
A3: Investor Name | M3: -1.2560225e+08 | P3: -55914.34 | Q3: -13952542 | T3: -1.2560225e+08 | W3: -55914.34 | X3: -13952542 | AT3: -328344.71
A4: 1999 Britta Biesecker Declaration of Trust DTD 5/12/99 | M4: -332165.64 | P4: -147.87014 | Q4: -36898.661 | T4: -320756.45 | W4: -142.79111 | X4: -35631.27 | AT4: -868.33498
A5: 1999 Frederick N Biesecker II Declaration of Trust DTD 5/12/99 | M5: -465031.9 | P5: -207.01819 | Q5: -51658.126 | T5: -449059.03 | W5: -199.90755 | X5: -49883.778 | AT5: -1215.669
A6: 1999 Lissa Biesecker Longacre Declaration of Trust DTD 5/12/99 | M6: -398598.77 | P6: -177.44416 | Q6: -44278.394 | T6: -384907.74 | W6: -171.34933 | X6: -42757.524 | AT6: -1042.002
A7: Abigail Levy | M7: -498248.46 | P7: -221.80521 | Q7: -55347.992 | T7: -481134.67 | W7: -214.18666 | X7: -53446.905 | AT7: -1302.5025
A8: AKWT LLC | M8: -52017.352 | P8: -23.156558 | Q8: -5778.354 | T8: -50230.665 | W8: -22.361179 | X8: -5579.8796 | AT8: -135.98181
A9: Alexander S. Bloomingdale | M9: -95795.216 | P9: -42.645144 | Q9: -10641.423 | T9: -92504.851 | W9: -41.180373 | X9: -10275.913 | AT9: -250.42427
A10: Alexander Sharpe Moore | M10: -104034.7 | P10: -46.313113 | Q10: -11556.707 | T10: -100461.32 | W10: -44.722355 | X10: -11159.759 | AT10: -271.96361
A11: All Dogs Go To Heaven, LLC | M11: -347642.47 | P11: -154.75996 | Q11: -38617.907 | T11: -335701.68 | W11: -149.44428 | X11: -37291.463 | AT11: -908.79394
A12: Alten Investments LLC | M12: -664331.28 | P12: -295.74027 | Q12: -73797.323 | T12: -641512.89 | W12: -285.58222 | X12: -71262.539 | AT12: -1736.67
A13: Avery Ryan Klann | M13: -260086.75 | P13: -115.78278 | Q13: -28891.769 | T13: -251153.31 | W13: -111.80589 | X13: -27899.397 | AT13: -679.90904
A14: BBR Real Assets Fund 2024 LLC | M14: -6643312.8 | P14: -2957.4027 | Q14: -737973.23 | T14: -6415128.9 | W14: -2855.8222 | X14: -712625.39 | AT14: -17366.7
... A40: In God We Trust 2017 Living Trust | M40: -66433.128 | P40: -29.574027 | Q40: -7379.7323 | T40: -64151.289 | W40: -28.558222 | X40: -7126.2539 | AT40: -173.667
A41: James and Natelie Bloomingdale | Q41: 0 | AT41: 0
A42: James Campbell and Patricia Campbell | M42: -104034.7 | P42: -46.313113 | Q42: -11556.707 | T42: -100461.32 | W42: -44.722355 | X42: -11159.759 | AT42: -271.96361
A43: James Kane | M43: -104034.7 | P43: -46.313113 | Q43: -11556.707 | T43: -100461.32 | W43: -44.722355 | X43: -11159.759 | AT43: -271.96361
A44: James Thorp | M44: -130043.37 | P44: -57.891392 | Q44: -14445.884 | T44: -125576.66 | W44: -55.902944 | X44: -13949.698 | AT44: -339.95452
A45: Jeffrey A. Lipsitz Revocable Trust | M45: -664331.28 | P45: -295.74027 | Q45: -73797.323 | T45: -641512.89 | W45: -285.58222 | X45: -71262.539 | AT45: -1736.67
A46: Jeffrey D Furber Revocable Trust | M46: -332165.64 | P46: -147.87014 | Q46: -36898.661 | T46: -320756.45 | W46: -142.79111 | X46: -35631.27 | AT46: -868.33498
A47: Jeremy M. Jacobs Trust U/A/D April 1, 1973 fbo Margaret L. Reichenback | M47: -996496.92 | P47: -443.61041 | Q47: -110695.98 | T47: -962269.34 | W47: -428.37332 | X47: -106893.81 | AT47: -2605.005
A48: John Mark Comer | M48: -66433.128 | P48: -29.574027 | Q48: -7379.7323 | T48: -64151.289 | W48: -28.558222 | X48: -7126.2539 | AT48: -173.667
A49: Landscape I, LP | M49: -498248.46 | P49: -221.80521 | Q49: -55347.992 | T49: -481134.67 | W49: -214.18666 | X49: -53446.905 | AT49: -1302.5025
A50: Lisa Bell Trust, Elisabeth B. Bell, Trustee | M50: -156052.05 | P50: -69.469671 | Q50: -17335.061 | T50: -150691.99 | W50: -67.083534 | X50: -16739.638 | AT50: -407.94543
A51: Madten Investments LLC | M51: -664331.28 | P51: -295.74027 | Q51: -73797.323 | T51: -641512.89 | W51: -285.58222 | X51: -71262.539 | AT51: -1736.67
A52: Matt McCoy | M52: -78026.021 | P52: -34.734834 | Q52: -8667.5303 | T52: -75345.991 | W52: -33.541765 | X52: -8369.8188 | AT52: -203.9727
A53: Matterhorn Holdings, LLC | M53: -66433.128 | P53: -29.574027 | Q53: -7379.7323 | T53: -64151.289 | W53: -28.558222 | X53: -7126.2539 | AT53: -173.667
... A56: Nahas Investments II LLC | M56: -260086.75 | P56: -115.78278 | Q56: -28891.769 | T56: -251153.31 | W56: -111.80589 | X56: -27899.397 | AT56: -679.90904
A57: Odyssey Holdings, LLC | M57: -467133.76 | P57: -207.95388 | Q57: -51891.612 | T57: -451088.7 | W57: -200.8111 | X57: -50109.244 | AT57: -1221.1636 | BB57: -9544.3131
A58: Pease River Holdings LLC | M58: -52017.352 | P58: -23.156558 | Q58: -5778.354 | T58: -50230.665 | W58: -22.361179 | X58: -5579.8796 | AT58: -135.98181
A59: PT Burros, LLC | M59: -218889.32 | P59: -97.442931 | Q59: -24315.347 | T59: -211370.93 | W59: -94.09597 | X59: -23480.166 | AT59: -572.21226
A60: Robert D. Falese III | M60: -583010.76 | P60: -259.53883 | Q60: -64763.823 | T60: -562985.56 | W60: -250.62421 | X60: -62539.321 | AT60: -1524.0849
A61: Robert Parker Yates | M61: -26008.676 | P61: -11.578279 | Q61: -2889.177 | T61: -25115.332 | W61: -11.180589 | X61: -2789.9398 | AT61: -67.990907
A62: Robert S. Shafir & Donna R. Shafir TEN/COM | M62: -996496.92 | P62: -443.61041 | Q62: -110695.98 | T62: -962269.34 | W62: -428.37332 | X62: -106893.81 | AT62: -2605.005
A63: Robert S. Shafir 2011 Children's Trust | M63: -664331.28 | P63: -295.74027 | Q63: -73797.323 | T63: -641512.89 | W63: -285.58222 | X63: -71262.539 | AT63: -1736.67
A64: Romar Partners, LP | M64: -664331.28 | P64: -295.74027 | Q64: -73797.323 | T64: -641512.89 | W64: -285.58222 | X64: -71262.539 | AT64: -1736.67
A65: Steven and Chani Laufer 2012 Dynasty Trust | M65: -1328662.6 | P65: -591.48055 | Q65: -147594.65 | T65: -1283025.8 | W65: -571.16443 | X65: -142525.08 | AT65: -3473.3399
A66: Steven M. Laufer 2012 Trust | M66: -664331.28 | P66: -295.74027 | Q66: -73797.323 | T66: -641512.89 | W66: -285.58222 | X66: -71262.539 | AT66: -1736.67
A67: Stewart Tate | M67: -347642.47 | P67: -154.75996 | Q67: -38617.907 | T67: -335701.68 | W67: -149.44428 | X67: -37291.463 | AT67: -908.79394
...

Sheet True-Up
S2: Correction
A3: Investor Name | S3: Contribution - Investment (Rebalanced) | U3: Contribution - Org Exp (Rebalanced) | V3: Contribution - General (Rebalanced)
A5: 1999 Britta Biesecker Declaration of Trust DTD 5/12/99 | S5: 851.8011 | U5: 0.37919619 | V5: -1187.5718
A6: 1999 Frederick N Biesecker II Declaration of Trust DTD 5/12/99 | S6: 1192.5215 | U6: 0.53087467 | V6: -1662.6005
A7: 1999 Lissa Biesecker Longacre Declaration of Trust DTD 5/12/99 | S7: 1022.1613 | U7: 0.45503543 | V7: -1425.0861
A8: Abigail Levy | S8: 1277.7017 | U8: 0.56879429 | V8: -1781.3576
A9: AKWT LLC | S9: 133.3926 | U9: 0.059382366 | V9: -185.9745
A10: Alexander S. Bloomingdale | S10: 245.65596 | U10: 0.10935863 | V10: -342.49085
A11: Alexander Sharpe Moore | S11: 266.78518 | U11: 0.11876473 | V11: -371.94897
A12: All Dogs Go To Heaven, LLC | S12: 891.48969 | U12: 0.39686435 | V12: -1242.9051
A13: Alten Investments LLC | S13: 1703.6022 | U13: 0.75839238 | V13: -2375.1435
A14: Avery Ryan Klann | S14: 666.96296 | U14: 0.29691182 | V14: -929.87244
A15: BBR Real Assets Fund 2024 LLC | S15: 17036.022 | U15: 7.5839238 | V15: -23751.435
A16: Belclaire Asset Management, LLC | S16: 1558.4526 | U16: 0.69377617 | V16: -2172.7776
... A84: Argos Holdings, LLC | S84: 666.96296 | U84: 0.29691182 | V84: -929.87244

Sheet Closing Interest
A1: CLRF Subsequent Close — Closing Interest (fund administrator schedule, values pinned)
O18: 4541702
O25: 327055.93
O26: 1288.7779
O29: 328344.71

Sheet Management Fees - New Investor
A1: CLRF Subsequent Close — Management Fees, New Investor (fund administrator schedule, values pinned)
M20: 9508.8323
M34: 35.480718

Sheet Subsequent Close - OLD B4 25k
A1: CLRF Subsequent Close — prior ($25k) basis variant (fund administrator schedule, value pinned)
U82: -147745.92

Sheet May 26 Distribution Checking
A1: CLRF Subsequent Close — May 2026 Distribution Checking (reconstructed from workpaper results; col Y = contribution reallocation, col AA = cash distribution)
A3: Investor Name | Y3: Contribution reallocation (Y) | AA3: Cash distribution (AA)
A4: 1999 Britta Biesecker Declaration of Trust DTD 5/12/99 | Y4: 5107.5 | AA4: -8777.9
A5: 1999 Frederick N Biesecker II Declaration of Trust DTD 5/12/99 | Y5: 7150.49 | AA5: -12289.05
A6: 1999 Lissa Biesecker Longacre Declaration of Trust DTD 5/12/99 | Y6: 6128.99 | AA6: -10533.47
A7: Abigail Levy | Y7: 7661.24 | AA7: -13166.84
A8: AKWT LLC | Y8: 799.84 | AA8: -1374.62
A9: Alexander S. Bloomingdale | Y9: 1472.98 | AA9: -2531.51
A10: Alexander Sharpe Moore | Y10: 1599.67 | AA10: -2749.25
A11: All Dogs Go To Heaven, LLC | Y11: 5345.47 | AA11: -9186.89
A12: Alten Investments LLC | Y12: 10214.99 | AA12: -17555.79
A13: Avery Ryan Klann | Y13: 3999.18 | AA13: -6873.12
A14: BBR Real Assets Fund 2024 LLC | Y14: 102149.9 | AA14: -175557.91
A15: Belclaire Asset Management, LLC | Y15: 9344.66 | AA15: -16060.01
... A81: Palmatum HR Illiquid, LLC | Y81: 20429.98 | AA81: -35111.58
A82: Legacy Knight Strategic Opportunities Fund LLC - CL Rail Series | Y82: 170590.34
A83: James Bloomingdale | Y83: 255.37
